telegram.vendor.ptb_urllib3.urllib3.connectionpool - WARNING - Retrying (Retry(total=2, connect=None, read=None, redirect=None)) after connection broken by 'NewConnectionError('<telegram.vendor.ptb_urllib3.urllib3.contrib.socks.SOCKSHTTPSConnection object at 0x10372f610>: Failed to establish a new connection: 0x01: General SOCKS server failure')': /bot1007684944:AAHyQ5_tF2_qer8lWGyWytHILaAOf5uYT_8/getMe
telegram.vendor.ptb_urllib3.urllib3.connectionpool - WARNING - Retrying (Retry(total=1, connect=None, read=None, redirect=None)) after connection broken by 'NewConnectionError('<telegram.vendor.ptb_urllib3.urllib3.contrib.socks.SOCKSHTTPSConnection object at 0x10372f910>: Failed to establish a new connection: 0x01: General SOCKS server failure')': /bot1007684944:AAHyQ5_tF2_qer8lWGyWytHILaAOf5uYT_8/getMe
telegram.vendor.ptb_urllib3.urllib3.connectionpool - WARNING - Retrying (Retry(total=0, connect=None, read=None, redirect=None)) after connection broken by 'NewConnectionError('<telegram.vendor.ptb_urllib3.urllib3.contrib.socks.SOCKSHTTPSConnection object at 0x10375db20>: Failed to establish a new connection: 0x01: General SOCKS server failure')': /bot1007684944:AAHyQ5_tF2_qer8lWGyWytHILaAOf5uYT_8/getMe
telegram.vendor.ptb_urllib3.urllib3.connectionpool - WARNING - Retrying (Retry(total=2, connect=None, read=None, redirect=None)) after connection broken by 'NewConnectionError('<telegram.vendor.ptb_urllib3.urllib3.contrib.socks.SOCKSHTTPSConnection object at 0x10239a610>: Failed to establish a new connection: 0x01: General SOCKS server failure')': /bot6056645493:AAF_wNP3RDXygUAZreqWePS90wuHUcJHNpQ/getMe
telegram.vendor.ptb_urllib3.urllib3.connectionpool - WARNING - Retrying (Retry(total=1, connect=None, read=None, redirect=None)) after connection broken by 'NewConnectionError('<telegram.vendor.ptb_urllib3.urllib3.contrib.socks.SOCKSHTTPSConnection object at 0x10239a910>: Failed to establish a new connection: 0x01: General SOCKS server failure')': /bot6056645493:AAF_wNP3RDXygUAZreqWePS90wuHUcJHNpQ/getMe
telegram.vendor.ptb_urllib3.urllib3.connectionpool - WARNING - Retrying (Retry(total=0, connect=None, read=None, redirect=None)) after connection broken by 'NewConnectionError('<telegram.vendor.ptb_urllib3.urllib3.contrib.socks.SOCKSHTTPSConnection object at 0x10239ae80>: Failed to establish a new connection: 0x01: General SOCKS server failure')': /bot6056645493:AAF_wNP3RDXygUAZreqWePS90wuHUcJHNpQ/getMe
telegram.vendor.ptb_urllib3.urllib3.connectionpool - WARNING - Retrying (Retry(total=2, connect=None, read=None, redirect=None)) after connection broken by 'NewConnectionError('<telegram.vendor.ptb_urllib3.urllib3.contrib.socks.SOCKSHTTPSConnection object at 0x102bc56a0>: Failed to establish a new connection: 0x01: General SOCKS server failure')': /bot6056645493:AAF_wNP3RDXygUAZreqWePS90wuHUcJHNpQ/getMe
telegram.vendor.ptb_urllib3.urllib3.connectionpool - WARNING - Retrying (Retry(total=1, connect=None, read=None, redirect=None)) after connection broken by 'NewConnectionError('<telegram.vendor.ptb_urllib3.urllib3.contrib.socks.SOCKSHTTPSConnection object at 0x102bc57c0>: Failed to establish a new connection: 0x01: General SOCKS server failure')': /bot6056645493:AAF_wNP3RDXygUAZreqWePS90wuHUcJHNpQ/getMe
telegram.vendor.ptb_urllib3.urllib3.connectionpool - WARNING - Retrying (Retry(total=0, connect=None, read=None, redirect=None)) after connection broken by 'NewConnectionError('<telegram.vendor.ptb_urllib3.urllib3.contrib.socks.SOCKSHTTPSConnection object at 0x102be35e0>: Failed to establish a new connection: 0x01: General SOCKS server failure')': /bot6056645493:AAF_wNP3RDXygUAZreqWePS90wuHUcJHNpQ/getMe
telegram.vendor.ptb_urllib3.urllib3.connectionpool - WARNING - Retrying (Retry(total=2, connect=None, read=None, redirect=None)) after connection broken by 'NewConnectionError('<telegram.vendor.ptb_urllib3.urllib3.contrib.socks.SOCKSHTTPSConnection object at 0x106ec7f40>: Failed to establish a new connection: 0x01: General SOCKS server failure')': /bot6056645493:AAF_wNP3RDXygUAZreqWePS90wuHUcJHNpQ/getMe
telegram.vendor.ptb_urllib3.urllib3.connectionpool - WARNING - Retrying (Retry(total=1, connect=None, read=None, redirect=None)) after connection broken by 'NewConnectionError('<telegram.vendor.ptb_urllib3.urllib3.contrib.socks.SOCKSHTTPSConnection object at 0x106ede5b0>: Failed to establish a new connection: 0x01: General SOCKS server failure')': /bot6056645493:AAF_wNP3RDXygUAZreqWePS90wuHUcJHNpQ/getMe
telegram.vendor.ptb_urllib3.urllib3.connectionpool - WARNING - Retrying (Retry(total=0, connect=None, read=None, redirect=None)) after connection broken by 'NewConnectionError('<telegram.vendor.ptb_urllib3.urllib3.contrib.socks.SOCKSHTTPSConnection object at 0x106ede6a0>: Failed to establish a new connection: 0x01: General SOCKS server failure')': /bot6056645493:AAF_wNP3RDXygUAZreqWePS90wuHUcJHNpQ/getMe
telegram.ext.updater - INFO - Received signal 2 (SIGINT), stopping...
telegram.ext.dispatcher - ERROR - No error handlers are registered, logging exception.
Traceback (most recent call last):
  File "/Users/konstantin_slepchenko/PycharmProjects/mbot/venv/lib/python3.9/site-packages/telegram/ext/dispatcher.py", line 372, in process_update
    handler.handle_update(update, self, check, context)
  File "/Users/konstantin_slepchenko/PycharmProjects/mbot/venv/lib/python3.9/site-packages/telegram/ext/handler.py", line 120, in handle_update
    return self.callback(dispatcher.bot, update, **optional_args)
  File "/Users/konstantin_slepchenko/PycharmProjects/mbot/mbot_app/miklyx_bot.py", line 42, in taps
    text = get_tap()
  File "/Users/konstantin_slepchenko/PycharmProjects/mbot/mbot_app/service/get_from_db.py", line 7, in get_tap
    sections_tap = db.taps.find_one({'act_flg': 1})["menu"]["sections"][0]["items"]
  File "/Users/konstantin_slepchenko/PycharmProjects/mbot/venv/lib/python3.9/site-packages/pymongo/collection.py", line 1459, in find_one
    for result in cursor.limit(-1):
  File "/Users/konstantin_slepchenko/PycharmProjects/mbot/venv/lib/python3.9/site-packages/pymongo/cursor.py", line 1248, in next
    if len(self.__data) or self._refresh():
  File "/Users/konstantin_slepchenko/PycharmProjects/mbot/venv/lib/python3.9/site-packages/pymongo/cursor.py", line 1165, in _refresh
    self.__send_message(q)
  File "/Users/konstantin_slepchenko/PycharmProjects/mbot/venv/lib/python3.9/site-packages/pymongo/cursor.py", line 1052, in __send_message
    response = client._run_operation(
  File "/Users/konstantin_slepchenko/PycharmProjects/mbot/venv/lib/python3.9/site-packages/pymongo/_csot.py", line 105, in csot_wrapper
    return func(self, *args, **kwargs)
  File "/Users/konstantin_slepchenko/PycharmProjects/mbot/venv/lib/python3.9/site-packages/pymongo/mongo_client.py", line 1330, in _run_operation
    return self._retryable_read(
  File "/Users/konstantin_slepchenko/PycharmProjects/mbot/venv/lib/python3.9/site-packages/pymongo/_csot.py", line 105, in csot_wrapper
    return func(self, *args, **kwargs)
  File "/Users/konstantin_slepchenko/PycharmProjects/mbot/venv/lib/python3.9/site-packages/pymongo/mongo_client.py", line 1442, in _retryable_read
    with self._socket_from_server(read_pref, server, session) as (sock_info, read_pref):
  File "/Library/Developer/CommandLineTools/Library/Frameworks/Python3.framework/Versions/3.9/lib/python3.9/contextlib.py", line 117, in __enter__
    return next(self.gen)
  File "/Users/konstantin_slepchenko/PycharmProjects/mbot/venv/lib/python3.9/site-packages/pymongo/mongo_client.py", line 1282, in _socket_from_server
    with self._get_socket(server, session) as sock_info:
  File "/Library/Developer/CommandLineTools/Library/Frameworks/Python3.framework/Versions/3.9/lib/python3.9/contextlib.py", line 117, in __enter__
    return next(self.gen)
  File "/Users/konstantin_slepchenko/PycharmProjects/mbot/venv/lib/python3.9/site-packages/pymongo/mongo_client.py", line 1217, in _get_socket
    with server.get_socket(handler=err_handler) as sock_info:
  File "/Library/Developer/CommandLineTools/Library/Frameworks/Python3.framework/Versions/3.9/lib/python3.9/contextlib.py", line 117, in __enter__
    return next(self.gen)
  File "/Users/konstantin_slepchenko/PycharmProjects/mbot/venv/lib/python3.9/site-packages/pymongo/pool.py", line 1407, in get_socket
    sock_info = self._get_socket(handler=handler)
  File "/Users/konstantin_slepchenko/PycharmProjects/mbot/venv/lib/python3.9/site-packages/pymongo/pool.py", line 1520, in _get_socket
    sock_info = self.connect(handler=handler)
  File "/Users/konstantin_slepchenko/PycharmProjects/mbot/venv/lib/python3.9/site-packages/pymongo/pool.py", line 1378, in connect
    sock_info.authenticate()
  File "/Users/konstantin_slepchenko/PycharmProjects/mbot/venv/lib/python3.9/site-packages/pymongo/pool.py", line 870, in authenticate
    auth.authenticate(creds, self)
  File "/Users/konstantin_slepchenko/PycharmProjects/mbot/venv/lib/python3.9/site-packages/pymongo/auth.py", line 549, in authenticate
    auth_func(credentials, sock_info)
  File "/Users/konstantin_slepchenko/PycharmProjects/mbot/venv/lib/python3.9/site-packages/pymongo/auth.py", line 475, in _authenticate_default
    return _authenticate_scram(credentials, sock_info, "SCRAM-SHA-1")
  File "/Users/konstantin_slepchenko/PycharmProjects/mbot/venv/lib/python3.9/site-packages/pymongo/auth.py", line 241, in _authenticate_scram
    res = sock_info.command(source, cmd)
  File "/Users/konstantin_slepchenko/PycharmProjects/mbot/venv/lib/python3.9/site-packages/pymongo/pool.py", line 767, in command
    return command(
  File "/Users/konstantin_slepchenko/PycharmProjects/mbot/venv/lib/python3.9/site-packages/pymongo/network.py", line 166, in command
    helpers._check_command_response(
  File "/Users/konstantin_slepchenko/PycharmProjects/mbot/venv/lib/python3.9/site-packages/pymongo/helpers.py", line 181, in _check_command_response
    raise OperationFailure(errmsg, code, response, max_wire_version)
pymongo.errors.OperationFailure: bad auth : authentication failed, full error: {'ok': 0, 'errmsg': 'bad auth : authentication failed', 'code': 8000, 'codeName': 'AtlasError'}
telegram.ext.dispatcher - ERROR - No error handlers are registered, logging exception.
Traceback (most recent call last):
  File "/Users/konstantin_slepchenko/PycharmProjects/mbot/venv/lib/python3.9/site-packages/telegram/ext/dispatcher.py", line 372, in process_update
    handler.handle_update(update, self, check, context)
  File "/Users/konstantin_slepchenko/PycharmProjects/mbot/venv/lib/python3.9/site-packages/telegram/ext/handler.py", line 120, in handle_update
    return self.callback(dispatcher.bot, update, **optional_args)
  File "/Users/konstantin_slepchenko/PycharmProjects/mbot/mbot_app/miklyx_bot.py", line 114, in bottles_root
    text = get_bottle()
  File "/Users/konstantin_slepchenko/PycharmProjects/mbot/mbot_app/service/get_from_db.py", line 20, in get_bottle
    sections_bottle = db.bottles.find_one({"act_flg": 1})
  File "/Users/konstantin_slepchenko/PycharmProjects/mbot/venv/lib/python3.9/site-packages/pymongo/collection.py", line 1459, in find_one
    for result in cursor.limit(-1):
  File "/Users/konstantin_slepchenko/PycharmProjects/mbot/venv/lib/python3.9/site-packages/pymongo/cursor.py", line 1248, in next
    if len(self.__data) or self._refresh():
  File "/Users/konstantin_slepchenko/PycharmProjects/mbot/venv/lib/python3.9/site-packages/pymongo/cursor.py", line 1165, in _refresh
    self.__send_message(q)
  File "/Users/konstantin_slepchenko/PycharmProjects/mbot/venv/lib/python3.9/site-packages/pymongo/cursor.py", line 1052, in __send_message
    response = client._run_operation(
  File "/Users/konstantin_slepchenko/PycharmProjects/mbot/venv/lib/python3.9/site-packages/pymongo/_csot.py", line 105, in csot_wrapper
    return func(self, *args, **kwargs)
  File "/Users/konstantin_slepchenko/PycharmProjects/mbot/venv/lib/python3.9/site-packages/pymongo/mongo_client.py", line 1330, in _run_operation
    return self._retryable_read(
  File "/Users/konstantin_slepchenko/PycharmProjects/mbot/venv/lib/python3.9/site-packages/pymongo/_csot.py", line 105, in csot_wrapper
    return func(self, *args, **kwargs)
  File "/Users/konstantin_slepchenko/PycharmProjects/mbot/venv/lib/python3.9/site-packages/pymongo/mongo_client.py", line 1442, in _retryable_read
    with self._socket_from_server(read_pref, server, session) as (sock_info, read_pref):
  File "/Library/Developer/CommandLineTools/Library/Frameworks/Python3.framework/Versions/3.9/lib/python3.9/contextlib.py", line 117, in __enter__
    return next(self.gen)
  File "/Users/konstantin_slepchenko/PycharmProjects/mbot/venv/lib/python3.9/site-packages/pymongo/mongo_client.py", line 1282, in _socket_from_server
    with self._get_socket(server, session) as sock_info:
  File "/Library/Developer/CommandLineTools/Library/Frameworks/Python3.framework/Versions/3.9/lib/python3.9/contextlib.py", line 117, in __enter__
    return next(self.gen)
  File "/Users/konstantin_slepchenko/PycharmProjects/mbot/venv/lib/python3.9/site-packages/pymongo/mongo_client.py", line 1217, in _get_socket
    with server.get_socket(handler=err_handler) as sock_info:
  File "/Library/Developer/CommandLineTools/Library/Frameworks/Python3.framework/Versions/3.9/lib/python3.9/contextlib.py", line 117, in __enter__
    return next(self.gen)
  File "/Users/konstantin_slepchenko/PycharmProjects/mbot/venv/lib/python3.9/site-packages/pymongo/pool.py", line 1407, in get_socket
    sock_info = self._get_socket(handler=handler)
  File "/Users/konstantin_slepchenko/PycharmProjects/mbot/venv/lib/python3.9/site-packages/pymongo/pool.py", line 1520, in _get_socket
    sock_info = self.connect(handler=handler)
  File "/Users/konstantin_slepchenko/PycharmProjects/mbot/venv/lib/python3.9/site-packages/pymongo/pool.py", line 1378, in connect
    sock_info.authenticate()
  File "/Users/konstantin_slepchenko/PycharmProjects/mbot/venv/lib/python3.9/site-packages/pymongo/pool.py", line 870, in authenticate
    auth.authenticate(creds, self)
  File "/Users/konstantin_slepchenko/PycharmProjects/mbot/venv/lib/python3.9/site-packages/pymongo/auth.py", line 549, in authenticate
    auth_func(credentials, sock_info)
  File "/Users/konstantin_slepchenko/PycharmProjects/mbot/venv/lib/python3.9/site-packages/pymongo/auth.py", line 475, in _authenticate_default
    return _authenticate_scram(credentials, sock_info, "SCRAM-SHA-1")
  File "/Users/konstantin_slepchenko/PycharmProjects/mbot/venv/lib/python3.9/site-packages/pymongo/auth.py", line 241, in _authenticate_scram
    res = sock_info.command(source, cmd)
  File "/Users/konstantin_slepchenko/PycharmProjects/mbot/venv/lib/python3.9/site-packages/pymongo/pool.py", line 767, in command
    return command(
  File "/Users/konstantin_slepchenko/PycharmProjects/mbot/venv/lib/python3.9/site-packages/pymongo/network.py", line 166, in command
    helpers._check_command_response(
  File "/Users/konstantin_slepchenko/PycharmProjects/mbot/venv/lib/python3.9/site-packages/pymongo/helpers.py", line 181, in _check_command_response
    raise OperationFailure(errmsg, code, response, max_wire_version)
pymongo.errors.OperationFailure: bad auth : authentication failed, full error: {'ok': 0, 'errmsg': 'bad auth : authentication failed', 'code': 8000, 'codeName': 'AtlasError'}
telegram.ext.updater - INFO - Received signal 2 (SIGINT), stopping...
telegram.ext.dispatcher - ERROR - No error handlers are registered, logging exception.
Traceback (most recent call last):
  File "/Users/konstantin_slepchenko/PycharmProjects/mbot/venv/lib/python3.9/site-packages/telegram/ext/dispatcher.py", line 372, in process_update
    handler.handle_update(update, self, check, context)
  File "/Users/konstantin_slepchenko/PycharmProjects/mbot/venv/lib/python3.9/site-packages/telegram/ext/handler.py", line 120, in handle_update
    return self.callback(dispatcher.bot, update, **optional_args)
  File "/Users/konstantin_slepchenko/PycharmProjects/mbot/mbot_app/miklyx_bot.py", line 42, in taps
    text = get_tap()
  File "/Users/konstantin_slepchenko/PycharmProjects/mbot/mbot_app/service/get_from_db.py", line 14, in get_tap
    taps[k]["price"] = j["containers"][0]["price"]
IndexError: list index out of range
telegram.ext.updater - INFO - Received signal 2 (SIGINT), stopping...
telegram.ext.dispatcher - ERROR - No error handlers are registered, logging exception.
Traceback (most recent call last):
  File "/Users/konstantin_slepchenko/PycharmProjects/mbot/venv/lib/python3.9/site-packages/telegram/ext/dispatcher.py", line 372, in process_update
    handler.handle_update(update, self, check, context)
  File "/Users/konstantin_slepchenko/PycharmProjects/mbot/venv/lib/python3.9/site-packages/telegram/ext/handler.py", line 120, in handle_update
    return self.callback(dispatcher.bot, update, **optional_args)
  File "/Users/konstantin_slepchenko/PycharmProjects/mbot/mbot_app/miklyx_bot.py", line 42, in taps
    text = get_tap()
  File "/Users/konstantin_slepchenko/PycharmProjects/mbot/mbot_app/service/get_from_db.py", line 15, in get_tap
    taps[k]["price"] = j["containers"][0]["price"]
IndexError: list index out of range
telegram.ext.updater - INFO - Received signal 2 (SIGINT), stopping...
telegram.ext.dispatcher - ERROR - No error handlers are registered, logging exception.
Traceback (most recent call last):
  File "/Users/konstantin_slepchenko/PycharmProjects/mbot/venv/lib/python3.9/site-packages/telegram/ext/dispatcher.py", line 372, in process_update
    handler.handle_update(update, self, check, context)
  File "/Users/konstantin_slepchenko/PycharmProjects/mbot/venv/lib/python3.9/site-packages/telegram/ext/handler.py", line 120, in handle_update
    return self.callback(dispatcher.bot, update, **optional_args)
  File "/Users/konstantin_slepchenko/PycharmProjects/mbot/mbot_app/miklyx_bot.py", line 43, in taps
    menu_keyboard = ReplyKeyboardMarkup([['К корню пива'],['Корзина']],[['В начало']], resize_keyboard=True, one_time_keyboard=True)
TypeError: __init__() got multiple values for argument 'resize_keyboard'
telegram.ext.updater - INFO - Received signal 2 (SIGINT), stopping...
telegram.ext.dispatcher - ERROR - No error handlers are registered, logging exception.
Traceback (most recent call last):
  File "/Users/konstantin_slepchenko/PycharmProjects/mbot/venv/lib/python3.9/site-packages/telegram/ext/dispatcher.py", line 372, in process_update
    handler.handle_update(update, self, check, context)
  File "/Users/konstantin_slepchenko/PycharmProjects/mbot/venv/lib/python3.9/site-packages/telegram/ext/handler.py", line 120, in handle_update
    return self.callback(dispatcher.bot, update, **optional_args)
  File "/Users/konstantin_slepchenko/PycharmProjects/mbot/mbot_app/miklyx_bot.py", line 44, in taps
    menu_keyboard = ReplyKeyboardMarkup([['К корню пива'],['Корзина']],[['В начало']], resize_keyboard=True, one_time_keyboard=True)
TypeError: __init__() got multiple values for argument 'resize_keyboard'
telegram.ext.updater - INFO - Received signal 2 (SIGINT), stopping...
telegram.ext.dispatcher - ERROR - No error handlers are registered, logging exception.
Traceback (most recent call last):
  File "/Users/konstantin_slepchenko/PycharmProjects/mbot/venv/lib/python3.9/site-packages/telegram/ext/dispatcher.py", line 372, in process_update
    handler.handle_update(update, self, check, context)
  File "/Users/konstantin_slepchenko/PycharmProjects/mbot/venv/lib/python3.9/site-packages/telegram/ext/handler.py", line 120, in handle_update
    return self.callback(dispatcher.bot, update, **optional_args)
  File "/Users/konstantin_slepchenko/PycharmProjects/mbot/mbot_app/miklyx_bot.py", line 118, in bottles_root
    text = get_bottle()
  File "/Users/konstantin_slepchenko/PycharmProjects/mbot/mbot_app/service/get_from_db.py", line 28, in get_bottle
    bottles[f'bottle_info_{i}'][f'bottle_item_{j}']['price'] = j_item['containers'][0]['price']
IndexError: list index out of range
telegram.ext.updater - INFO - Received signal 2 (SIGINT), stopping...
telegram.ext.updater - INFO - Received signal 2 (SIGINT), stopping...
telegram.ext.updater - INFO - Received signal 2 (SIGINT), stopping...
telegram.ext.updater - INFO - Received signal 2 (SIGINT), stopping...
telegram.ext.dispatcher - ERROR - No error handlers are registered, logging exception.
Traceback (most recent call last):
  File "/Users/konstantin_slepchenko/PycharmProjects/mbot/venv/lib/python3.9/site-packages/telegram/ext/dispatcher.py", line 372, in process_update
    handler.handle_update(update, self, check, context)
  File "/Users/konstantin_slepchenko/PycharmProjects/mbot/venv/lib/python3.9/site-packages/telegram/ext/handler.py", line 120, in handle_update
    return self.callback(dispatcher.bot, update, **optional_args)
  File "/Users/konstantin_slepchenko/PycharmProjects/mbot/mbot_app/miklyx_bot.py", line 43, in taps
    menu_keyboard = ReplyKeyboardMarkup([['К корню пива'],['Корзина']],[['В начало']], resize_keyboard=True, one_time_keyboard=True)
TypeError: __init__() got multiple values for argument 'resize_keyboard'
telegram.ext.updater - INFO - Received signal 2 (SIGINT), stopping...
telegram.ext.updater - ERROR - Error while getting Updates: Conflict: terminated by other getUpdates request; make sure that only one bot instance is running
telegram.ext.dispatcher - ERROR - No error handlers are registered, logging exception.
Traceback (most recent call last):
  File "/Users/konstantin_slepchenko/PycharmProjects/mbot/venv/lib/python3.9/site-packages/telegram/ext/updater.py", line 332, in _network_loop_retry
    if not action_cb():
  File "/Users/konstantin_slepchenko/PycharmProjects/mbot/venv/lib/python3.9/site-packages/telegram/ext/updater.py", line 291, in polling_action_cb
    updates = self.bot.get_updates(
  File "/Users/konstantin_slepchenko/PycharmProjects/mbot/venv/lib/python3.9/site-packages/telegram/bot.py", line 66, in decorator
    result = func(self, *args, **kwargs)
  File "/Users/konstantin_slepchenko/PycharmProjects/mbot/venv/lib/python3.9/site-packages/telegram/bot.py", line 1982, in get_updates
    result = self._request.post(url, data, timeout=float(read_latency) + float(timeout))
  File "/Users/konstantin_slepchenko/PycharmProjects/mbot/venv/lib/python3.9/site-packages/telegram/utils/request.py", line 324, in post
    result = self._request_wrapper('POST', url,
  File "/Users/konstantin_slepchenko/PycharmProjects/mbot/venv/lib/python3.9/site-packages/telegram/utils/request.py", line 242, in _request_wrapper
    raise Conflict(message)
telegram.error.Conflict: Conflict: terminated by other getUpdates request; make sure that only one bot instance is running
telegram.ext.updater - ERROR - Error while getting Updates: Conflict: terminated by other getUpdates request; make sure that only one bot instance is running
telegram.ext.dispatcher - ERROR - No error handlers are registered, logging exception.
Traceback (most recent call last):
  File "/Users/konstantin_slepchenko/PycharmProjects/mbot/venv/lib/python3.9/site-packages/telegram/ext/updater.py", line 332, in _network_loop_retry
    if not action_cb():
  File "/Users/konstantin_slepchenko/PycharmProjects/mbot/venv/lib/python3.9/site-packages/telegram/ext/updater.py", line 291, in polling_action_cb
    updates = self.bot.get_updates(
  File "/Users/konstantin_slepchenko/PycharmProjects/mbot/venv/lib/python3.9/site-packages/telegram/bot.py", line 66, in decorator
    result = func(self, *args, **kwargs)
  File "/Users/konstantin_slepchenko/PycharmProjects/mbot/venv/lib/python3.9/site-packages/telegram/bot.py", line 1982, in get_updates
    result = self._request.post(url, data, timeout=float(read_latency) + float(timeout))
  File "/Users/konstantin_slepchenko/PycharmProjects/mbot/venv/lib/python3.9/site-packages/telegram/utils/request.py", line 324, in post
    result = self._request_wrapper('POST', url,
  File "/Users/konstantin_slepchenko/PycharmProjects/mbot/venv/lib/python3.9/site-packages/telegram/utils/request.py", line 242, in _request_wrapper
    raise Conflict(message)
telegram.error.Conflict: Conflict: terminated by other getUpdates request; make sure that only one bot instance is running
telegram.ext.updater - ERROR - Error while getting Updates: Conflict: terminated by other getUpdates request; make sure that only one bot instance is running
telegram.ext.updater - ERROR - Error while getting Updates: Conflict: terminated by other getUpdates request; make sure that only one bot instance is running
telegram.ext.dispatcher - ERROR - No error handlers are registered, logging exception.
Traceback (most recent call last):
  File "/Users/konstantin_slepchenko/PycharmProjects/mbot/venv/lib/python3.9/site-packages/telegram/ext/updater.py", line 332, in _network_loop_retry
    if not action_cb():
  File "/Users/konstantin_slepchenko/PycharmProjects/mbot/venv/lib/python3.9/site-packages/telegram/ext/updater.py", line 291, in polling_action_cb
    updates = self.bot.get_updates(
  File "/Users/konstantin_slepchenko/PycharmProjects/mbot/venv/lib/python3.9/site-packages/telegram/bot.py", line 66, in decorator
    result = func(self, *args, **kwargs)
  File "/Users/konstantin_slepchenko/PycharmProjects/mbot/venv/lib/python3.9/site-packages/telegram/bot.py", line 1982, in get_updates
    result = self._request.post(url, data, timeout=float(read_latency) + float(timeout))
  File "/Users/konstantin_slepchenko/PycharmProjects/mbot/venv/lib/python3.9/site-packages/telegram/utils/request.py", line 324, in post
    result = self._request_wrapper('POST', url,
  File "/Users/konstantin_slepchenko/PycharmProjects/mbot/venv/lib/python3.9/site-packages/telegram/utils/request.py", line 242, in _request_wrapper
    raise Conflict(message)
telegram.error.Conflict: Conflict: terminated by other getUpdates request; make sure that only one bot instance is running
telegram.ext.updater - ERROR - Error while getting Updates: Conflict: terminated by other getUpdates request; make sure that only one bot instance is running
telegram.ext.updater - ERROR - Error while getting Updates: Conflict: terminated by other getUpdates request; make sure that only one bot instance is running
telegram.ext.dispatcher - ERROR - No error handlers are registered, logging exception.
Traceback (most recent call last):
  File "/Users/konstantin_slepchenko/PycharmProjects/mbot/venv/lib/python3.9/site-packages/telegram/ext/updater.py", line 332, in _network_loop_retry
    if not action_cb():
  File "/Users/konstantin_slepchenko/PycharmProjects/mbot/venv/lib/python3.9/site-packages/telegram/ext/updater.py", line 291, in polling_action_cb
    updates = self.bot.get_updates(
  File "/Users/konstantin_slepchenko/PycharmProjects/mbot/venv/lib/python3.9/site-packages/telegram/bot.py", line 66, in decorator
    result = func(self, *args, **kwargs)
  File "/Users/konstantin_slepchenko/PycharmProjects/mbot/venv/lib/python3.9/site-packages/telegram/bot.py", line 1982, in get_updates
    result = self._request.post(url, data, timeout=float(read_latency) + float(timeout))
  File "/Users/konstantin_slepchenko/PycharmProjects/mbot/venv/lib/python3.9/site-packages/telegram/utils/request.py", line 324, in post
    result = self._request_wrapper('POST', url,
  File "/Users/konstantin_slepchenko/PycharmProjects/mbot/venv/lib/python3.9/site-packages/telegram/utils/request.py", line 242, in _request_wrapper
    raise Conflict(message)
telegram.error.Conflict: Conflict: terminated by other getUpdates request; make sure that only one bot instance is running
telegram.ext.updater - ERROR - Error while getting Updates: Conflict: terminated by other getUpdates request; make sure that only one bot instance is running
telegram.ext.dispatcher - ERROR - No error handlers are registered, logging exception.
Traceback (most recent call last):
  File "/Users/konstantin_slepchenko/PycharmProjects/mbot/venv/lib/python3.9/site-packages/telegram/ext/dispatcher.py", line 372, in process_update
    handler.handle_update(update, self, check, context)
  File "/Users/konstantin_slepchenko/PycharmProjects/mbot/venv/lib/python3.9/site-packages/telegram/ext/handler.py", line 120, in handle_update
    return self.callback(dispatcher.bot, update, **optional_args)
  File "/Users/konstantin_slepchenko/PycharmProjects/mbot/mbot_app/miklyx_bot.py", line 43, in taps
    menu_keyboard = ReplyKeyboardMarkup([['К корню пива'],['Корзина']],[['В начало']], resize_keyboard=True, one_time_keyboard=True)
TypeError: __init__() got multiple values for argument 'resize_keyboard'
telegram.ext.dispatcher - ERROR - No error handlers are registered, logging exception.
Traceback (most recent call last):
  File "/Users/konstantin_slepchenko/PycharmProjects/mbot/venv/lib/python3.9/site-packages/telegram/ext/updater.py", line 332, in _network_loop_retry
    if not action_cb():
  File "/Users/konstantin_slepchenko/PycharmProjects/mbot/venv/lib/python3.9/site-packages/telegram/ext/updater.py", line 291, in polling_action_cb
    updates = self.bot.get_updates(
  File "/Users/konstantin_slepchenko/PycharmProjects/mbot/venv/lib/python3.9/site-packages/telegram/bot.py", line 66, in decorator
    result = func(self, *args, **kwargs)
  File "/Users/konstantin_slepchenko/PycharmProjects/mbot/venv/lib/python3.9/site-packages/telegram/bot.py", line 1982, in get_updates
    result = self._request.post(url, data, timeout=float(read_latency) + float(timeout))
  File "/Users/konstantin_slepchenko/PycharmProjects/mbot/venv/lib/python3.9/site-packages/telegram/utils/request.py", line 324, in post
    result = self._request_wrapper('POST', url,
  File "/Users/konstantin_slepchenko/PycharmProjects/mbot/venv/lib/python3.9/site-packages/telegram/utils/request.py", line 242, in _request_wrapper
    raise Conflict(message)
telegram.error.Conflict: Conflict: terminated by other getUpdates request; make sure that only one bot instance is running
telegram.ext.dispatcher - ERROR - No error handlers are registered, logging exception.
Traceback (most recent call last):
  File "/Users/konstantin_slepchenko/PycharmProjects/mbot/venv/lib/python3.9/site-packages/telegram/ext/updater.py", line 332, in _network_loop_retry
    if not action_cb():
  File "/Users/konstantin_slepchenko/PycharmProjects/mbot/venv/lib/python3.9/site-packages/telegram/ext/updater.py", line 291, in polling_action_cb
    updates = self.bot.get_updates(
  File "/Users/konstantin_slepchenko/PycharmProjects/mbot/venv/lib/python3.9/site-packages/telegram/bot.py", line 66, in decorator
    result = func(self, *args, **kwargs)
  File "/Users/konstantin_slepchenko/PycharmProjects/mbot/venv/lib/python3.9/site-packages/telegram/bot.py", line 1982, in get_updates
    result = self._request.post(url, data, timeout=float(read_latency) + float(timeout))
  File "/Users/konstantin_slepchenko/PycharmProjects/mbot/venv/lib/python3.9/site-packages/telegram/utils/request.py", line 324, in post
    result = self._request_wrapper('POST', url,
  File "/Users/konstantin_slepchenko/PycharmProjects/mbot/venv/lib/python3.9/site-packages/telegram/utils/request.py", line 242, in _request_wrapper
    raise Conflict(message)
telegram.error.Conflict: Conflict: terminated by other getUpdates request; make sure that only one bot instance is running
telegram.ext.dispatcher - ERROR - No error handlers are registered, logging exception.
Traceback (most recent call last):
  File "/Users/konstantin_slepchenko/PycharmProjects/mbot/venv/lib/python3.9/site-packages/telegram/ext/updater.py", line 332, in _network_loop_retry
    if not action_cb():
  File "/Users/konstantin_slepchenko/PycharmProjects/mbot/venv/lib/python3.9/site-packages/telegram/ext/updater.py", line 291, in polling_action_cb
    updates = self.bot.get_updates(
  File "/Users/konstantin_slepchenko/PycharmProjects/mbot/venv/lib/python3.9/site-packages/telegram/bot.py", line 66, in decorator
    result = func(self, *args, **kwargs)
  File "/Users/konstantin_slepchenko/PycharmProjects/mbot/venv/lib/python3.9/site-packages/telegram/bot.py", line 1982, in get_updates
    result = self._request.post(url, data, timeout=float(read_latency) + float(timeout))
  File "/Users/konstantin_slepchenko/PycharmProjects/mbot/venv/lib/python3.9/site-packages/telegram/utils/request.py", line 324, in post
    result = self._request_wrapper('POST', url,
  File "/Users/konstantin_slepchenko/PycharmProjects/mbot/venv/lib/python3.9/site-packages/telegram/utils/request.py", line 242, in _request_wrapper
    raise Conflict(message)
telegram.error.Conflict: Conflict: terminated by other getUpdates request; make sure that only one bot instance is running
telegram.ext.updater - ERROR - Error while getting Updates: Conflict: terminated by other getUpdates request; make sure that only one bot instance is running
telegram.ext.dispatcher - ERROR - No error handlers are registered, logging exception.
Traceback (most recent call last):
  File "/Users/konstantin_slepchenko/PycharmProjects/mbot/venv/lib/python3.9/site-packages/telegram/ext/updater.py", line 332, in _network_loop_retry
    if not action_cb():
  File "/Users/konstantin_slepchenko/PycharmProjects/mbot/venv/lib/python3.9/site-packages/telegram/ext/updater.py", line 291, in polling_action_cb
    updates = self.bot.get_updates(
  File "/Users/konstantin_slepchenko/PycharmProjects/mbot/venv/lib/python3.9/site-packages/telegram/bot.py", line 66, in decorator
    result = func(self, *args, **kwargs)
  File "/Users/konstantin_slepchenko/PycharmProjects/mbot/venv/lib/python3.9/site-packages/telegram/bot.py", line 1982, in get_updates
    result = self._request.post(url, data, timeout=float(read_latency) + float(timeout))
  File "/Users/konstantin_slepchenko/PycharmProjects/mbot/venv/lib/python3.9/site-packages/telegram/utils/request.py", line 324, in post
    result = self._request_wrapper('POST', url,
  File "/Users/konstantin_slepchenko/PycharmProjects/mbot/venv/lib/python3.9/site-packages/telegram/utils/request.py", line 242, in _request_wrapper
    raise Conflict(message)
telegram.error.Conflict: Conflict: terminated by other getUpdates request; make sure that only one bot instance is running
telegram.ext.updater - ERROR - Error while getting Updates: Conflict: terminated by other getUpdates request; make sure that only one bot instance is running
telegram.ext.dispatcher - ERROR - No error handlers are registered, logging exception.
Traceback (most recent call last):
  File "/Users/konstantin_slepchenko/PycharmProjects/mbot/venv/lib/python3.9/site-packages/telegram/ext/updater.py", line 332, in _network_loop_retry
    if not action_cb():
  File "/Users/konstantin_slepchenko/PycharmProjects/mbot/venv/lib/python3.9/site-packages/telegram/ext/updater.py", line 291, in polling_action_cb
    updates = self.bot.get_updates(
  File "/Users/konstantin_slepchenko/PycharmProjects/mbot/venv/lib/python3.9/site-packages/telegram/bot.py", line 66, in decorator
    result = func(self, *args, **kwargs)
  File "/Users/konstantin_slepchenko/PycharmProjects/mbot/venv/lib/python3.9/site-packages/telegram/bot.py", line 1982, in get_updates
    result = self._request.post(url, data, timeout=float(read_latency) + float(timeout))
  File "/Users/konstantin_slepchenko/PycharmProjects/mbot/venv/lib/python3.9/site-packages/telegram/utils/request.py", line 324, in post
    result = self._request_wrapper('POST', url,
  File "/Users/konstantin_slepchenko/PycharmProjects/mbot/venv/lib/python3.9/site-packages/telegram/utils/request.py", line 242, in _request_wrapper
    raise Conflict(message)
telegram.error.Conflict: Conflict: terminated by other getUpdates request; make sure that only one bot instance is running
telegram.ext.updater - ERROR - Error while getting Updates: Conflict: terminated by other getUpdates request; make sure that only one bot instance is running
telegram.ext.dispatcher - ERROR - No error handlers are registered, logging exception.
Traceback (most recent call last):
  File "/Users/konstantin_slepchenko/PycharmProjects/mbot/venv/lib/python3.9/site-packages/telegram/ext/updater.py", line 332, in _network_loop_retry
    if not action_cb():
  File "/Users/konstantin_slepchenko/PycharmProjects/mbot/venv/lib/python3.9/site-packages/telegram/ext/updater.py", line 291, in polling_action_cb
    updates = self.bot.get_updates(
  File "/Users/konstantin_slepchenko/PycharmProjects/mbot/venv/lib/python3.9/site-packages/telegram/bot.py", line 66, in decorator
    result = func(self, *args, **kwargs)
  File "/Users/konstantin_slepchenko/PycharmProjects/mbot/venv/lib/python3.9/site-packages/telegram/bot.py", line 1982, in get_updates
    result = self._request.post(url, data, timeout=float(read_latency) + float(timeout))
  File "/Users/konstantin_slepchenko/PycharmProjects/mbot/venv/lib/python3.9/site-packages/telegram/utils/request.py", line 324, in post
    result = self._request_wrapper('POST', url,
  File "/Users/konstantin_slepchenko/PycharmProjects/mbot/venv/lib/python3.9/site-packages/telegram/utils/request.py", line 242, in _request_wrapper
    raise Conflict(message)
telegram.error.Conflict: Conflict: terminated by other getUpdates request; make sure that only one bot instance is running
telegram.ext.updater - ERROR - Error while getting Updates: Conflict: terminated by other getUpdates request; make sure that only one bot instance is running
telegram.ext.dispatcher - ERROR - No error handlers are registered, logging exception.
Traceback (most recent call last):
  File "/Users/konstantin_slepchenko/PycharmProjects/mbot/venv/lib/python3.9/site-packages/telegram/ext/updater.py", line 332, in _network_loop_retry
    if not action_cb():
  File "/Users/konstantin_slepchenko/PycharmProjects/mbot/venv/lib/python3.9/site-packages/telegram/ext/updater.py", line 291, in polling_action_cb
    updates = self.bot.get_updates(
  File "/Users/konstantin_slepchenko/PycharmProjects/mbot/venv/lib/python3.9/site-packages/telegram/bot.py", line 66, in decorator
    result = func(self, *args, **kwargs)
  File "/Users/konstantin_slepchenko/PycharmProjects/mbot/venv/lib/python3.9/site-packages/telegram/bot.py", line 1982, in get_updates
    result = self._request.post(url, data, timeout=float(read_latency) + float(timeout))
  File "/Users/konstantin_slepchenko/PycharmProjects/mbot/venv/lib/python3.9/site-packages/telegram/utils/request.py", line 324, in post
    result = self._request_wrapper('POST', url,
  File "/Users/konstantin_slepchenko/PycharmProjects/mbot/venv/lib/python3.9/site-packages/telegram/utils/request.py", line 242, in _request_wrapper
    raise Conflict(message)
telegram.error.Conflict: Conflict: terminated by other getUpdates request; make sure that only one bot instance is running
telegram.ext.updater - INFO - Received signal 2 (SIGINT), stopping...
telegram.ext.updater - INFO - Received signal 2 (SIGINT), stopping...
telegram.ext.dispatcher - ERROR - No error handlers are registered, logging exception.
Traceback (most recent call last):
  File "/Users/konstantin_slepchenko/PycharmProjects/mbot/venv/lib/python3.9/site-packages/telegram/ext/dispatcher.py", line 372, in process_update
    handler.handle_update(update, self, check, context)
  File "/Users/konstantin_slepchenko/PycharmProjects/mbot/venv/lib/python3.9/site-packages/telegram/ext/handler.py", line 120, in handle_update
    return self.callback(dispatcher.bot, update, **optional_args)
  File "/Users/konstantin_slepchenko/PycharmProjects/mbot/mbot_app/miklyx_bot.py", line 43, in taps
    menu_keyboard = ReplyKeyboardMarkup([['К корню пива'],['Корзина']],[['В начало']], resize_keyboard=True, one_time_keyboard=True)
TypeError: __init__() got multiple values for argument 'resize_keyboard'
telegram.ext.dispatcher - ERROR - No error handlers are registered, logging exception.
Traceback (most recent call last):
  File "/Users/konstantin_slepchenko/PycharmProjects/mbot/venv/lib/python3.9/site-packages/telegram/ext/dispatcher.py", line 372, in process_update
    handler.handle_update(update, self, check, context)
  File "/Users/konstantin_slepchenko/PycharmProjects/mbot/venv/lib/python3.9/site-packages/telegram/ext/handler.py", line 120, in handle_update
    return self.callback(dispatcher.bot, update, **optional_args)
  File "/Users/konstantin_slepchenko/PycharmProjects/mbot/mbot_app/miklyx_bot.py", line 43, in taps
    menu_keyboard = ReplyKeyboardMarkup([['К корню пива'],['Корзина']],[['В начало']], resize_keyboard=True, one_time_keyboard=True)
TypeError: __init__() got multiple values for argument 'resize_keyboard'
telegram.ext.updater - INFO - Received signal 2 (SIGINT), stopping...
telegram.ext.dispatcher - ERROR - No error handlers are registered, logging exception.
Traceback (most recent call last):
  File "/Users/konstantin_slepchenko/PycharmProjects/mbot/venv/lib/python3.9/site-packages/telegram/ext/dispatcher.py", line 372, in process_update
    handler.handle_update(update, self, check, context)
  File "/Users/konstantin_slepchenko/PycharmProjects/mbot/venv/lib/python3.9/site-packages/telegram/ext/handler.py", line 120, in handle_update
    return self.callback(dispatcher.bot, update, **optional_args)
  File "/Users/konstantin_slepchenko/PycharmProjects/mbot/mbot_app/miklyx_bot.py", line 49, in taps
    about = text[i]['name']+', Стиль: '+text[i]['style']+', Пивоварня: '+text[i]['brewery']+', ABV: '+text[i]['abv']+', IBU: '+text[i]['ibu']+'\n'+'Цена: '+text[i]['price']
TypeError: can only concatenate str (not "NoneType") to str
telegram.ext.updater - INFO - Received signal 2 (SIGINT), stopping...
telegram.ext.dispatcher - ERROR - No error handlers are registered, logging exception.
Traceback (most recent call last):
  File "/Users/konstantin_slepchenko/PycharmProjects/mbot/venv/lib/python3.9/site-packages/telegram/ext/dispatcher.py", line 372, in process_update
    handler.handle_update(update, self, check, context)
  File "/Users/konstantin_slepchenko/PycharmProjects/mbot/venv/lib/python3.9/site-packages/telegram/ext/handler.py", line 120, in handle_update
    return self.callback(dispatcher.bot, update, **optional_args)
  File "/Users/konstantin_slepchenko/PycharmProjects/mbot/mbot_app/miklyx_bot.py", line 45, in taps
    for i in range(text):
TypeError: 'list' object cannot be interpreted as an integer
telegram.ext.dispatcher - ERROR - No error handlers are registered, logging exception.
Traceback (most recent call last):
  File "/Users/konstantin_slepchenko/PycharmProjects/mbot/venv/lib/python3.9/site-packages/telegram/ext/dispatcher.py", line 372, in process_update
    handler.handle_update(update, self, check, context)
  File "/Users/konstantin_slepchenko/PycharmProjects/mbot/venv/lib/python3.9/site-packages/telegram/ext/handler.py", line 120, in handle_update
    return self.callback(dispatcher.bot, update, **optional_args)
  File "/Users/konstantin_slepchenko/PycharmProjects/mbot/mbot_app/miklyx_bot.py", line 45, in taps
    for i in range(text):
TypeError: 'list' object cannot be interpreted as an integer
telegram.ext.updater - INFO - Received signal 2 (SIGINT), stopping...
telegram.ext.dispatcher - ERROR - No error handlers are registered, logging exception.
Traceback (most recent call last):
  File "/Users/konstantin_slepchenko/PycharmProjects/mbot/venv/lib/python3.9/site-packages/telegram/ext/dispatcher.py", line 372, in process_update
    handler.handle_update(update, self, check, context)
  File "/Users/konstantin_slepchenko/PycharmProjects/mbot/venv/lib/python3.9/site-packages/telegram/ext/handler.py", line 120, in handle_update
    return self.callback(dispatcher.bot, update, **optional_args)
  File "/Users/konstantin_slepchenko/PycharmProjects/mbot/mbot_app/miklyx_bot.py", line 46, in taps
    about = text[i]['name']+', Стиль: '+text[i]['style']+', Пивоварня: '+text[i]['brewery']+', ABV: '+text[i]['abv']+', IBU: '+text[i]['ibu']+'\n'+'Цена: '+text[i]['price']
TypeError: can only concatenate str (not "NoneType") to str
telegram.ext.updater - INFO - Received signal 2 (SIGINT), stopping...
telegram.ext.dispatcher - ERROR - No error handlers are registered, logging exception.
Traceback (most recent call last):
  File "/Users/konstantin_slepchenko/PycharmProjects/mbot/venv/lib/python3.9/site-packages/telegram/ext/dispatcher.py", line 372, in process_update
    handler.handle_update(update, self, check, context)
  File "/Users/konstantin_slepchenko/PycharmProjects/mbot/venv/lib/python3.9/site-packages/telegram/ext/handler.py", line 120, in handle_update
    return self.callback(dispatcher.bot, update, **optional_args)
  File "/Users/konstantin_slepchenko/PycharmProjects/mbot/mbot_app/miklyx_bot.py", line 46, in taps
    about = text[i]['name']+', Стиль: '+text[i]['style']+', Пивоварня: '+text[i]['brewery']+', ABV: '+text[i]['abv']+', IBU: '+text[i]['ibu']+'\n'+'Цена: '+text[i]['price']
TypeError: can only concatenate str (not "NoneType") to str
telegram.ext.updater - INFO - Received signal 2 (SIGINT), stopping...
telegram.ext.dispatcher - ERROR - No error handlers are registered, logging exception.
Traceback (most recent call last):
  File "/Users/konstantin_slepchenko/PycharmProjects/mbot/venv/lib/python3.9/site-packages/telegram/ext/dispatcher.py", line 372, in process_update
    handler.handle_update(update, self, check, context)
  File "/Users/konstantin_slepchenko/PycharmProjects/mbot/venv/lib/python3.9/site-packages/telegram/ext/handler.py", line 120, in handle_update
    return self.callback(dispatcher.bot, update, **optional_args)
  File "/Users/konstantin_slepchenko/PycharmProjects/mbot/mbot_app/miklyx_bot.py", line 48, in taps
    update.message.reply_text(reply_markup=menu_keyboard)
  File "/Users/konstantin_slepchenko/PycharmProjects/mbot/venv/lib/python3.9/site-packages/telegram/message.py", line 478, in reply_text
    return self.bot.send_message(self.chat_id, *args, **kwargs)
  File "/Users/konstantin_slepchenko/PycharmProjects/mbot/venv/lib/python3.9/site-packages/telegram/bot.py", line 66, in decorator
    result = func(self, *args, **kwargs)
TypeError: send_message() missing 1 required positional argument: 'text'
telegram.ext.updater - INFO - Received signal 2 (SIGINT), stopping...
telegram.ext.updater - INFO - Received signal 2 (SIGINT), stopping...
telegram.ext.dispatcher - ERROR - No error handlers are registered, logging exception.
Traceback (most recent call last):
  File "/Users/konstantin_slepchenko/PycharmProjects/mbot/venv/lib/python3.9/site-packages/telegram/ext/dispatcher.py", line 372, in process_update
    handler.handle_update(update, self, check, context)
  File "/Users/konstantin_slepchenko/PycharmProjects/mbot/venv/lib/python3.9/site-packages/telegram/ext/handler.py", line 120, in handle_update
    return self.callback(dispatcher.bot, update, **optional_args)
  File "/Users/konstantin_slepchenko/PycharmProjects/mbot/mbot_app/miklyx_bot.py", line 145, in bottles_section
    update.message.reply_text(reply_markup=menu_keyboard)
  File "/Users/konstantin_slepchenko/PycharmProjects/mbot/venv/lib/python3.9/site-packages/telegram/message.py", line 478, in reply_text
    return self.bot.send_message(self.chat_id, *args, **kwargs)
  File "/Users/konstantin_slepchenko/PycharmProjects/mbot/venv/lib/python3.9/site-packages/telegram/bot.py", line 66, in decorator
    result = func(self, *args, **kwargs)
TypeError: send_message() missing 1 required positional argument: 'text'
telegram.ext.updater - INFO - Received signal 2 (SIGINT), stopping...
telegram.ext.updater - ERROR - Error while getting Updates: Conflict: terminated by other getUpdates request; make sure that only one bot instance is running
telegram.ext.dispatcher - ERROR - No error handlers are registered, logging exception.
Traceback (most recent call last):
  File "/Users/konstantin_slepchenko/PycharmProjects/mbot/venv/lib/python3.9/site-packages/telegram/ext/updater.py", line 332, in _network_loop_retry
    if not action_cb():
  File "/Users/konstantin_slepchenko/PycharmProjects/mbot/venv/lib/python3.9/site-packages/telegram/ext/updater.py", line 291, in polling_action_cb
    updates = self.bot.get_updates(
  File "/Users/konstantin_slepchenko/PycharmProjects/mbot/venv/lib/python3.9/site-packages/telegram/bot.py", line 66, in decorator
    result = func(self, *args, **kwargs)
  File "/Users/konstantin_slepchenko/PycharmProjects/mbot/venv/lib/python3.9/site-packages/telegram/bot.py", line 1982, in get_updates
    result = self._request.post(url, data, timeout=float(read_latency) + float(timeout))
  File "/Users/konstantin_slepchenko/PycharmProjects/mbot/venv/lib/python3.9/site-packages/telegram/utils/request.py", line 324, in post
    result = self._request_wrapper('POST', url,
  File "/Users/konstantin_slepchenko/PycharmProjects/mbot/venv/lib/python3.9/site-packages/telegram/utils/request.py", line 242, in _request_wrapper
    raise Conflict(message)
telegram.error.Conflict: Conflict: terminated by other getUpdates request; make sure that only one bot instance is running
telegram.ext.updater - ERROR - Error while getting Updates: Conflict: terminated by other getUpdates request; make sure that only one bot instance is running
telegram.ext.dispatcher - ERROR - No error handlers are registered, logging exception.
Traceback (most recent call last):
  File "/Users/konstantin_slepchenko/PycharmProjects/mbot/venv/lib/python3.9/site-packages/telegram/ext/updater.py", line 332, in _network_loop_retry
    if not action_cb():
  File "/Users/konstantin_slepchenko/PycharmProjects/mbot/venv/lib/python3.9/site-packages/telegram/ext/updater.py", line 291, in polling_action_cb
    updates = self.bot.get_updates(
  File "/Users/konstantin_slepchenko/PycharmProjects/mbot/venv/lib/python3.9/site-packages/telegram/bot.py", line 66, in decorator
    result = func(self, *args, **kwargs)
  File "/Users/konstantin_slepchenko/PycharmProjects/mbot/venv/lib/python3.9/site-packages/telegram/bot.py", line 1982, in get_updates
    result = self._request.post(url, data, timeout=float(read_latency) + float(timeout))
  File "/Users/konstantin_slepchenko/PycharmProjects/mbot/venv/lib/python3.9/site-packages/telegram/utils/request.py", line 324, in post
    result = self._request_wrapper('POST', url,
  File "/Users/konstantin_slepchenko/PycharmProjects/mbot/venv/lib/python3.9/site-packages/telegram/utils/request.py", line 242, in _request_wrapper
    raise Conflict(message)
telegram.error.Conflict: Conflict: terminated by other getUpdates request; make sure that only one bot instance is running
telegram.ext.updater - ERROR - Error while getting Updates: Conflict: terminated by other getUpdates request; make sure that only one bot instance is running
telegram.ext.updater - ERROR - Error while getting Updates: Conflict: terminated by other getUpdates request; make sure that only one bot instance is running
telegram.ext.dispatcher - ERROR - No error handlers are registered, logging exception.
Traceback (most recent call last):
  File "/Users/konstantin_slepchenko/PycharmProjects/mbot/venv/lib/python3.9/site-packages/telegram/ext/updater.py", line 332, in _network_loop_retry
    if not action_cb():
  File "/Users/konstantin_slepchenko/PycharmProjects/mbot/venv/lib/python3.9/site-packages/telegram/ext/updater.py", line 291, in polling_action_cb
    updates = self.bot.get_updates(
  File "/Users/konstantin_slepchenko/PycharmProjects/mbot/venv/lib/python3.9/site-packages/telegram/bot.py", line 66, in decorator
    result = func(self, *args, **kwargs)
  File "/Users/konstantin_slepchenko/PycharmProjects/mbot/venv/lib/python3.9/site-packages/telegram/bot.py", line 1982, in get_updates
    result = self._request.post(url, data, timeout=float(read_latency) + float(timeout))
  File "/Users/konstantin_slepchenko/PycharmProjects/mbot/venv/lib/python3.9/site-packages/telegram/utils/request.py", line 324, in post
    result = self._request_wrapper('POST', url,
  File "/Users/konstantin_slepchenko/PycharmProjects/mbot/venv/lib/python3.9/site-packages/telegram/utils/request.py", line 242, in _request_wrapper
    raise Conflict(message)
telegram.error.Conflict: Conflict: terminated by other getUpdates request; make sure that only one bot instance is running
telegram.ext.updater - ERROR - Error while getting Updates: Conflict: terminated by other getUpdates request; make sure that only one bot instance is running
telegram.ext.dispatcher - ERROR - No error handlers are registered, logging exception.
Traceback (most recent call last):
  File "/Users/konstantin_slepchenko/PycharmProjects/mbot/venv/lib/python3.9/site-packages/telegram/ext/updater.py", line 332, in _network_loop_retry
    if not action_cb():
  File "/Users/konstantin_slepchenko/PycharmProjects/mbot/venv/lib/python3.9/site-packages/telegram/ext/updater.py", line 291, in polling_action_cb
    updates = self.bot.get_updates(
  File "/Users/konstantin_slepchenko/PycharmProjects/mbot/venv/lib/python3.9/site-packages/telegram/bot.py", line 66, in decorator
    result = func(self, *args, **kwargs)
  File "/Users/konstantin_slepchenko/PycharmProjects/mbot/venv/lib/python3.9/site-packages/telegram/bot.py", line 1982, in get_updates
    result = self._request.post(url, data, timeout=float(read_latency) + float(timeout))
  File "/Users/konstantin_slepchenko/PycharmProjects/mbot/venv/lib/python3.9/site-packages/telegram/utils/request.py", line 324, in post
    result = self._request_wrapper('POST', url,
  File "/Users/konstantin_slepchenko/PycharmProjects/mbot/venv/lib/python3.9/site-packages/telegram/utils/request.py", line 242, in _request_wrapper
    raise Conflict(message)
telegram.error.Conflict: Conflict: terminated by other getUpdates request; make sure that only one bot instance is running
telegram.ext.dispatcher - ERROR - No error handlers are registered, logging exception.
Traceback (most recent call last):
  File "/Users/konstantin_slepchenko/PycharmProjects/mbot/venv/lib/python3.9/site-packages/telegram/ext/updater.py", line 332, in _network_loop_retry
    if not action_cb():
  File "/Users/konstantin_slepchenko/PycharmProjects/mbot/venv/lib/python3.9/site-packages/telegram/ext/updater.py", line 291, in polling_action_cb
    updates = self.bot.get_updates(
  File "/Users/konstantin_slepchenko/PycharmProjects/mbot/venv/lib/python3.9/site-packages/telegram/bot.py", line 66, in decorator
    result = func(self, *args, **kwargs)
  File "/Users/konstantin_slepchenko/PycharmProjects/mbot/venv/lib/python3.9/site-packages/telegram/bot.py", line 1982, in get_updates
    result = self._request.post(url, data, timeout=float(read_latency) + float(timeout))
  File "/Users/konstantin_slepchenko/PycharmProjects/mbot/venv/lib/python3.9/site-packages/telegram/utils/request.py", line 324, in post
    result = self._request_wrapper('POST', url,
  File "/Users/konstantin_slepchenko/PycharmProjects/mbot/venv/lib/python3.9/site-packages/telegram/utils/request.py", line 242, in _request_wrapper
    raise Conflict(message)
telegram.error.Conflict: Conflict: terminated by other getUpdates request; make sure that only one bot instance is running
telegram.ext.updater - ERROR - Error while getting Updates: Conflict: terminated by other getUpdates request; make sure that only one bot instance is running
telegram.ext.dispatcher - ERROR - No error handlers are registered, logging exception.
Traceback (most recent call last):
  File "/Users/konstantin_slepchenko/PycharmProjects/mbot/venv/lib/python3.9/site-packages/telegram/ext/updater.py", line 332, in _network_loop_retry
    if not action_cb():
  File "/Users/konstantin_slepchenko/PycharmProjects/mbot/venv/lib/python3.9/site-packages/telegram/ext/updater.py", line 291, in polling_action_cb
    updates = self.bot.get_updates(
  File "/Users/konstantin_slepchenko/PycharmProjects/mbot/venv/lib/python3.9/site-packages/telegram/bot.py", line 66, in decorator
    result = func(self, *args, **kwargs)
  File "/Users/konstantin_slepchenko/PycharmProjects/mbot/venv/lib/python3.9/site-packages/telegram/bot.py", line 1982, in get_updates
    result = self._request.post(url, data, timeout=float(read_latency) + float(timeout))
  File "/Users/konstantin_slepchenko/PycharmProjects/mbot/venv/lib/python3.9/site-packages/telegram/utils/request.py", line 324, in post
    result = self._request_wrapper('POST', url,
  File "/Users/konstantin_slepchenko/PycharmProjects/mbot/venv/lib/python3.9/site-packages/telegram/utils/request.py", line 242, in _request_wrapper
    raise Conflict(message)
telegram.error.Conflict: Conflict: terminated by other getUpdates request; make sure that only one bot instance is running
telegram.ext.updater - ERROR - Error while getting Updates: Conflict: terminated by other getUpdates request; make sure that only one bot instance is running
telegram.ext.dispatcher - ERROR - No error handlers are registered, logging exception.
Traceback (most recent call last):
  File "/Users/konstantin_slepchenko/PycharmProjects/mbot/venv/lib/python3.9/site-packages/telegram/ext/updater.py", line 332, in _network_loop_retry
    if not action_cb():
  File "/Users/konstantin_slepchenko/PycharmProjects/mbot/venv/lib/python3.9/site-packages/telegram/ext/updater.py", line 291, in polling_action_cb
    updates = self.bot.get_updates(
  File "/Users/konstantin_slepchenko/PycharmProjects/mbot/venv/lib/python3.9/site-packages/telegram/bot.py", line 66, in decorator
    result = func(self, *args, **kwargs)
  File "/Users/konstantin_slepchenko/PycharmProjects/mbot/venv/lib/python3.9/site-packages/telegram/bot.py", line 1982, in get_updates
    result = self._request.post(url, data, timeout=float(read_latency) + float(timeout))
  File "/Users/konstantin_slepchenko/PycharmProjects/mbot/venv/lib/python3.9/site-packages/telegram/utils/request.py", line 324, in post
    result = self._request_wrapper('POST', url,
  File "/Users/konstantin_slepchenko/PycharmProjects/mbot/venv/lib/python3.9/site-packages/telegram/utils/request.py", line 242, in _request_wrapper
    raise Conflict(message)
telegram.error.Conflict: Conflict: terminated by other getUpdates request; make sure that only one bot instance is running
telegram.ext.updater - ERROR - Error while getting Updates: Conflict: terminated by other getUpdates request; make sure that only one bot instance is running
telegram.ext.updater - ERROR - Error while getting Updates: Conflict: terminated by other getUpdates request; make sure that only one bot instance is running
telegram.ext.dispatcher - ERROR - No error handlers are registered, logging exception.
Traceback (most recent call last):
  File "/Users/konstantin_slepchenko/PycharmProjects/mbot/venv/lib/python3.9/site-packages/telegram/ext/updater.py", line 332, in _network_loop_retry
    if not action_cb():
  File "/Users/konstantin_slepchenko/PycharmProjects/mbot/venv/lib/python3.9/site-packages/telegram/ext/updater.py", line 291, in polling_action_cb
    updates = self.bot.get_updates(
  File "/Users/konstantin_slepchenko/PycharmProjects/mbot/venv/lib/python3.9/site-packages/telegram/bot.py", line 66, in decorator
    result = func(self, *args, **kwargs)
  File "/Users/konstantin_slepchenko/PycharmProjects/mbot/venv/lib/python3.9/site-packages/telegram/bot.py", line 1982, in get_updates
    result = self._request.post(url, data, timeout=float(read_latency) + float(timeout))
  File "/Users/konstantin_slepchenko/PycharmProjects/mbot/venv/lib/python3.9/site-packages/telegram/utils/request.py", line 324, in post
    result = self._request_wrapper('POST', url,
  File "/Users/konstantin_slepchenko/PycharmProjects/mbot/venv/lib/python3.9/site-packages/telegram/utils/request.py", line 242, in _request_wrapper
    raise Conflict(message)
telegram.error.Conflict: Conflict: terminated by other getUpdates request; make sure that only one bot instance is running
telegram.ext.updater - ERROR - Error while getting Updates: Conflict: terminated by other getUpdates request; make sure that only one bot instance is running
telegram.ext.updater - ERROR - Error while getting Updates: Conflict: terminated by other getUpdates request; make sure that only one bot instance is running
telegram.ext.dispatcher - ERROR - No error handlers are registered, logging exception.
Traceback (most recent call last):
  File "/Users/konstantin_slepchenko/PycharmProjects/mbot/venv/lib/python3.9/site-packages/telegram/ext/updater.py", line 332, in _network_loop_retry
    if not action_cb():
  File "/Users/konstantin_slepchenko/PycharmProjects/mbot/venv/lib/python3.9/site-packages/telegram/ext/updater.py", line 291, in polling_action_cb
    updates = self.bot.get_updates(
  File "/Users/konstantin_slepchenko/PycharmProjects/mbot/venv/lib/python3.9/site-packages/telegram/bot.py", line 66, in decorator
    result = func(self, *args, **kwargs)
  File "/Users/konstantin_slepchenko/PycharmProjects/mbot/venv/lib/python3.9/site-packages/telegram/bot.py", line 1982, in get_updates
    result = self._request.post(url, data, timeout=float(read_latency) + float(timeout))
  File "/Users/konstantin_slepchenko/PycharmProjects/mbot/venv/lib/python3.9/site-packages/telegram/utils/request.py", line 324, in post
    result = self._request_wrapper('POST', url,
  File "/Users/konstantin_slepchenko/PycharmProjects/mbot/venv/lib/python3.9/site-packages/telegram/utils/request.py", line 242, in _request_wrapper
    raise Conflict(message)
telegram.error.Conflict: Conflict: terminated by other getUpdates request; make sure that only one bot instance is running
telegram.ext.updater - ERROR - Error while getting Updates: Conflict: terminated by other getUpdates request; make sure that only one bot instance is running
telegram.ext.updater - ERROR - Error while getting Updates: Conflict: terminated by other getUpdates request; make sure that only one bot instance is running
telegram.ext.dispatcher - ERROR - No error handlers are registered, logging exception.
Traceback (most recent call last):
  File "/Users/konstantin_slepchenko/PycharmProjects/mbot/venv/lib/python3.9/site-packages/telegram/ext/updater.py", line 332, in _network_loop_retry
    if not action_cb():
  File "/Users/konstantin_slepchenko/PycharmProjects/mbot/venv/lib/python3.9/site-packages/telegram/ext/updater.py", line 291, in polling_action_cb
    updates = self.bot.get_updates(
  File "/Users/konstantin_slepchenko/PycharmProjects/mbot/venv/lib/python3.9/site-packages/telegram/bot.py", line 66, in decorator
    result = func(self, *args, **kwargs)
  File "/Users/konstantin_slepchenko/PycharmProjects/mbot/venv/lib/python3.9/site-packages/telegram/bot.py", line 1982, in get_updates
    result = self._request.post(url, data, timeout=float(read_latency) + float(timeout))
  File "/Users/konstantin_slepchenko/PycharmProjects/mbot/venv/lib/python3.9/site-packages/telegram/utils/request.py", line 324, in post
    result = self._request_wrapper('POST', url,
  File "/Users/konstantin_slepchenko/PycharmProjects/mbot/venv/lib/python3.9/site-packages/telegram/utils/request.py", line 242, in _request_wrapper
    raise Conflict(message)
telegram.error.Conflict: Conflict: terminated by other getUpdates request; make sure that only one bot instance is running
telegram.ext.updater - ERROR - Error while getting Updates: Conflict: terminated by other getUpdates request; make sure that only one bot instance is running
telegram.ext.updater - ERROR - Error while getting Updates: Conflict: terminated by other getUpdates request; make sure that only one bot instance is running
telegram.ext.dispatcher - ERROR - No error handlers are registered, logging exception.
Traceback (most recent call last):
  File "/Users/konstantin_slepchenko/PycharmProjects/mbot/venv/lib/python3.9/site-packages/telegram/ext/updater.py", line 332, in _network_loop_retry
    if not action_cb():
  File "/Users/konstantin_slepchenko/PycharmProjects/mbot/venv/lib/python3.9/site-packages/telegram/ext/updater.py", line 291, in polling_action_cb
    updates = self.bot.get_updates(
  File "/Users/konstantin_slepchenko/PycharmProjects/mbot/venv/lib/python3.9/site-packages/telegram/bot.py", line 66, in decorator
    result = func(self, *args, **kwargs)
  File "/Users/konstantin_slepchenko/PycharmProjects/mbot/venv/lib/python3.9/site-packages/telegram/bot.py", line 1982, in get_updates
    result = self._request.post(url, data, timeout=float(read_latency) + float(timeout))
  File "/Users/konstantin_slepchenko/PycharmProjects/mbot/venv/lib/python3.9/site-packages/telegram/utils/request.py", line 324, in post
    result = self._request_wrapper('POST', url,
  File "/Users/konstantin_slepchenko/PycharmProjects/mbot/venv/lib/python3.9/site-packages/telegram/utils/request.py", line 242, in _request_wrapper
    raise Conflict(message)
telegram.error.Conflict: Conflict: terminated by other getUpdates request; make sure that only one bot instance is running
telegram.ext.updater - ERROR - Error while getting Updates: Conflict: terminated by other getUpdates request; make sure that only one bot instance is running
telegram.ext.updater - ERROR - Error while getting Updates: Conflict: terminated by other getUpdates request; make sure that only one bot instance is running
telegram.ext.dispatcher - ERROR - No error handlers are registered, logging exception.
Traceback (most recent call last):
  File "/Users/konstantin_slepchenko/PycharmProjects/mbot/venv/lib/python3.9/site-packages/telegram/ext/updater.py", line 332, in _network_loop_retry
    if not action_cb():
  File "/Users/konstantin_slepchenko/PycharmProjects/mbot/venv/lib/python3.9/site-packages/telegram/ext/updater.py", line 291, in polling_action_cb
    updates = self.bot.get_updates(
  File "/Users/konstantin_slepchenko/PycharmProjects/mbot/venv/lib/python3.9/site-packages/telegram/bot.py", line 66, in decorator
    result = func(self, *args, **kwargs)
  File "/Users/konstantin_slepchenko/PycharmProjects/mbot/venv/lib/python3.9/site-packages/telegram/bot.py", line 1982, in get_updates
    result = self._request.post(url, data, timeout=float(read_latency) + float(timeout))
  File "/Users/konstantin_slepchenko/PycharmProjects/mbot/venv/lib/python3.9/site-packages/telegram/utils/request.py", line 324, in post
    result = self._request_wrapper('POST', url,
  File "/Users/konstantin_slepchenko/PycharmProjects/mbot/venv/lib/python3.9/site-packages/telegram/utils/request.py", line 242, in _request_wrapper
    raise Conflict(message)
telegram.error.Conflict: Conflict: terminated by other getUpdates request; make sure that only one bot instance is running
telegram.ext.updater - ERROR - Error while getting Updates: Conflict: terminated by other getUpdates request; make sure that only one bot instance is running
telegram.ext.dispatcher - ERROR - No error handlers are registered, logging exception.
Traceback (most recent call last):
  File "/Users/konstantin_slepchenko/PycharmProjects/mbot/venv/lib/python3.9/site-packages/telegram/ext/updater.py", line 332, in _network_loop_retry
    if not action_cb():
  File "/Users/konstantin_slepchenko/PycharmProjects/mbot/venv/lib/python3.9/site-packages/telegram/ext/updater.py", line 291, in polling_action_cb
    updates = self.bot.get_updates(
  File "/Users/konstantin_slepchenko/PycharmProjects/mbot/venv/lib/python3.9/site-packages/telegram/bot.py", line 66, in decorator
    result = func(self, *args, **kwargs)
  File "/Users/konstantin_slepchenko/PycharmProjects/mbot/venv/lib/python3.9/site-packages/telegram/bot.py", line 1982, in get_updates
    result = self._request.post(url, data, timeout=float(read_latency) + float(timeout))
  File "/Users/konstantin_slepchenko/PycharmProjects/mbot/venv/lib/python3.9/site-packages/telegram/utils/request.py", line 324, in post
    result = self._request_wrapper('POST', url,
  File "/Users/konstantin_slepchenko/PycharmProjects/mbot/venv/lib/python3.9/site-packages/telegram/utils/request.py", line 242, in _request_wrapper
    raise Conflict(message)
telegram.error.Conflict: Conflict: terminated by other getUpdates request; make sure that only one bot instance is running
telegram.ext.updater - ERROR - Error while getting Updates: Conflict: terminated by other getUpdates request; make sure that only one bot instance is running
telegram.ext.updater - ERROR - Error while getting Updates: Conflict: terminated by other getUpdates request; make sure that only one bot instance is running
telegram.ext.dispatcher - ERROR - No error handlers are registered, logging exception.
Traceback (most recent call last):
  File "/Users/konstantin_slepchenko/PycharmProjects/mbot/venv/lib/python3.9/site-packages/telegram/ext/updater.py", line 332, in _network_loop_retry
    if not action_cb():
  File "/Users/konstantin_slepchenko/PycharmProjects/mbot/venv/lib/python3.9/site-packages/telegram/ext/updater.py", line 291, in polling_action_cb
    updates = self.bot.get_updates(
  File "/Users/konstantin_slepchenko/PycharmProjects/mbot/venv/lib/python3.9/site-packages/telegram/bot.py", line 66, in decorator
    result = func(self, *args, **kwargs)
  File "/Users/konstantin_slepchenko/PycharmProjects/mbot/venv/lib/python3.9/site-packages/telegram/bot.py", line 1982, in get_updates
    result = self._request.post(url, data, timeout=float(read_latency) + float(timeout))
  File "/Users/konstantin_slepchenko/PycharmProjects/mbot/venv/lib/python3.9/site-packages/telegram/utils/request.py", line 324, in post
    result = self._request_wrapper('POST', url,
  File "/Users/konstantin_slepchenko/PycharmProjects/mbot/venv/lib/python3.9/site-packages/telegram/utils/request.py", line 242, in _request_wrapper
    raise Conflict(message)
telegram.error.Conflict: Conflict: terminated by other getUpdates request; make sure that only one bot instance is running
telegram.ext.updater - ERROR - Error while getting Updates: Conflict: terminated by other getUpdates request; make sure that only one bot instance is running
telegram.ext.updater - ERROR - Error while getting Updates: Conflict: terminated by other getUpdates request; make sure that only one bot instance is running
telegram.ext.dispatcher - ERROR - No error handlers are registered, logging exception.
Traceback (most recent call last):
  File "/Users/konstantin_slepchenko/PycharmProjects/mbot/venv/lib/python3.9/site-packages/telegram/ext/updater.py", line 332, in _network_loop_retry
    if not action_cb():
  File "/Users/konstantin_slepchenko/PycharmProjects/mbot/venv/lib/python3.9/site-packages/telegram/ext/updater.py", line 291, in polling_action_cb
    updates = self.bot.get_updates(
  File "/Users/konstantin_slepchenko/PycharmProjects/mbot/venv/lib/python3.9/site-packages/telegram/bot.py", line 66, in decorator
    result = func(self, *args, **kwargs)
  File "/Users/konstantin_slepchenko/PycharmProjects/mbot/venv/lib/python3.9/site-packages/telegram/bot.py", line 1982, in get_updates
    result = self._request.post(url, data, timeout=float(read_latency) + float(timeout))
  File "/Users/konstantin_slepchenko/PycharmProjects/mbot/venv/lib/python3.9/site-packages/telegram/utils/request.py", line 324, in post
    result = self._request_wrapper('POST', url,
  File "/Users/konstantin_slepchenko/PycharmProjects/mbot/venv/lib/python3.9/site-packages/telegram/utils/request.py", line 242, in _request_wrapper
    raise Conflict(message)
telegram.error.Conflict: Conflict: terminated by other getUpdates request; make sure that only one bot instance is running
telegram.ext.updater - ERROR - Error while getting Updates: Conflict: terminated by other getUpdates request; make sure that only one bot instance is running
telegram.ext.updater - ERROR - Error while getting Updates: Conflict: terminated by other getUpdates request; make sure that only one bot instance is running
telegram.ext.dispatcher - ERROR - No error handlers are registered, logging exception.
Traceback (most recent call last):
  File "/Users/konstantin_slepchenko/PycharmProjects/mbot/venv/lib/python3.9/site-packages/telegram/ext/updater.py", line 332, in _network_loop_retry
    if not action_cb():
  File "/Users/konstantin_slepchenko/PycharmProjects/mbot/venv/lib/python3.9/site-packages/telegram/ext/updater.py", line 291, in polling_action_cb
    updates = self.bot.get_updates(
  File "/Users/konstantin_slepchenko/PycharmProjects/mbot/venv/lib/python3.9/site-packages/telegram/bot.py", line 66, in decorator
    result = func(self, *args, **kwargs)
  File "/Users/konstantin_slepchenko/PycharmProjects/mbot/venv/lib/python3.9/site-packages/telegram/bot.py", line 1982, in get_updates
    result = self._request.post(url, data, timeout=float(read_latency) + float(timeout))
  File "/Users/konstantin_slepchenko/PycharmProjects/mbot/venv/lib/python3.9/site-packages/telegram/utils/request.py", line 324, in post
    result = self._request_wrapper('POST', url,
  File "/Users/konstantin_slepchenko/PycharmProjects/mbot/venv/lib/python3.9/site-packages/telegram/utils/request.py", line 242, in _request_wrapper
    raise Conflict(message)
telegram.error.Conflict: Conflict: terminated by other getUpdates request; make sure that only one bot instance is running
telegram.ext.updater - ERROR - Error while getting Updates: Conflict: terminated by other getUpdates request; make sure that only one bot instance is running
telegram.ext.updater - ERROR - Error while getting Updates: Conflict: terminated by other getUpdates request; make sure that only one bot instance is running
telegram.ext.dispatcher - ERROR - No error handlers are registered, logging exception.
Traceback (most recent call last):
  File "/Users/konstantin_slepchenko/PycharmProjects/mbot/venv/lib/python3.9/site-packages/telegram/ext/updater.py", line 332, in _network_loop_retry
    if not action_cb():
  File "/Users/konstantin_slepchenko/PycharmProjects/mbot/venv/lib/python3.9/site-packages/telegram/ext/updater.py", line 291, in polling_action_cb
    updates = self.bot.get_updates(
  File "/Users/konstantin_slepchenko/PycharmProjects/mbot/venv/lib/python3.9/site-packages/telegram/bot.py", line 66, in decorator
    result = func(self, *args, **kwargs)
  File "/Users/konstantin_slepchenko/PycharmProjects/mbot/venv/lib/python3.9/site-packages/telegram/bot.py", line 1982, in get_updates
    result = self._request.post(url, data, timeout=float(read_latency) + float(timeout))
  File "/Users/konstantin_slepchenko/PycharmProjects/mbot/venv/lib/python3.9/site-packages/telegram/utils/request.py", line 324, in post
    result = self._request_wrapper('POST', url,
  File "/Users/konstantin_slepchenko/PycharmProjects/mbot/venv/lib/python3.9/site-packages/telegram/utils/request.py", line 242, in _request_wrapper
    raise Conflict(message)
telegram.error.Conflict: Conflict: terminated by other getUpdates request; make sure that only one bot instance is running
telegram.ext.updater - ERROR - Error while getting Updates: Conflict: terminated by other getUpdates request; make sure that only one bot instance is running
telegram.ext.updater - ERROR - Error while getting Updates: Conflict: terminated by other getUpdates request; make sure that only one bot instance is running
telegram.ext.dispatcher - ERROR - No error handlers are registered, logging exception.
Traceback (most recent call last):
  File "/Users/konstantin_slepchenko/PycharmProjects/mbot/venv/lib/python3.9/site-packages/telegram/ext/updater.py", line 332, in _network_loop_retry
    if not action_cb():
  File "/Users/konstantin_slepchenko/PycharmProjects/mbot/venv/lib/python3.9/site-packages/telegram/ext/updater.py", line 291, in polling_action_cb
    updates = self.bot.get_updates(
  File "/Users/konstantin_slepchenko/PycharmProjects/mbot/venv/lib/python3.9/site-packages/telegram/bot.py", line 66, in decorator
    result = func(self, *args, **kwargs)
  File "/Users/konstantin_slepchenko/PycharmProjects/mbot/venv/lib/python3.9/site-packages/telegram/bot.py", line 1982, in get_updates
    result = self._request.post(url, data, timeout=float(read_latency) + float(timeout))
  File "/Users/konstantin_slepchenko/PycharmProjects/mbot/venv/lib/python3.9/site-packages/telegram/utils/request.py", line 324, in post
    result = self._request_wrapper('POST', url,
  File "/Users/konstantin_slepchenko/PycharmProjects/mbot/venv/lib/python3.9/site-packages/telegram/utils/request.py", line 242, in _request_wrapper
    raise Conflict(message)
telegram.error.Conflict: Conflict: terminated by other getUpdates request; make sure that only one bot instance is running
telegram.ext.updater - ERROR - Error while getting Updates: Conflict: terminated by other getUpdates request; make sure that only one bot instance is running
telegram.ext.updater - ERROR - Error while getting Updates: Conflict: terminated by other getUpdates request; make sure that only one bot instance is running
telegram.ext.dispatcher - ERROR - No error handlers are registered, logging exception.
Traceback (most recent call last):
  File "/Users/konstantin_slepchenko/PycharmProjects/mbot/venv/lib/python3.9/site-packages/telegram/ext/updater.py", line 332, in _network_loop_retry
    if not action_cb():
  File "/Users/konstantin_slepchenko/PycharmProjects/mbot/venv/lib/python3.9/site-packages/telegram/ext/updater.py", line 291, in polling_action_cb
    updates = self.bot.get_updates(
  File "/Users/konstantin_slepchenko/PycharmProjects/mbot/venv/lib/python3.9/site-packages/telegram/bot.py", line 66, in decorator
    result = func(self, *args, **kwargs)
  File "/Users/konstantin_slepchenko/PycharmProjects/mbot/venv/lib/python3.9/site-packages/telegram/bot.py", line 1982, in get_updates
    result = self._request.post(url, data, timeout=float(read_latency) + float(timeout))
  File "/Users/konstantin_slepchenko/PycharmProjects/mbot/venv/lib/python3.9/site-packages/telegram/utils/request.py", line 324, in post
    result = self._request_wrapper('POST', url,
  File "/Users/konstantin_slepchenko/PycharmProjects/mbot/venv/lib/python3.9/site-packages/telegram/utils/request.py", line 242, in _request_wrapper
    raise Conflict(message)
telegram.error.Conflict: Conflict: terminated by other getUpdates request; make sure that only one bot instance is running
telegram.ext.updater - ERROR - Error while getting Updates: Conflict: terminated by other getUpdates request; make sure that only one bot instance is running
telegram.ext.updater - ERROR - Error while getting Updates: Conflict: terminated by other getUpdates request; make sure that only one bot instance is running
telegram.ext.dispatcher - ERROR - No error handlers are registered, logging exception.
Traceback (most recent call last):
  File "/Users/konstantin_slepchenko/PycharmProjects/mbot/venv/lib/python3.9/site-packages/telegram/ext/updater.py", line 332, in _network_loop_retry
    if not action_cb():
  File "/Users/konstantin_slepchenko/PycharmProjects/mbot/venv/lib/python3.9/site-packages/telegram/ext/updater.py", line 291, in polling_action_cb
    updates = self.bot.get_updates(
  File "/Users/konstantin_slepchenko/PycharmProjects/mbot/venv/lib/python3.9/site-packages/telegram/bot.py", line 66, in decorator
    result = func(self, *args, **kwargs)
  File "/Users/konstantin_slepchenko/PycharmProjects/mbot/venv/lib/python3.9/site-packages/telegram/bot.py", line 1982, in get_updates
    result = self._request.post(url, data, timeout=float(read_latency) + float(timeout))
  File "/Users/konstantin_slepchenko/PycharmProjects/mbot/venv/lib/python3.9/site-packages/telegram/utils/request.py", line 324, in post
    result = self._request_wrapper('POST', url,
  File "/Users/konstantin_slepchenko/PycharmProjects/mbot/venv/lib/python3.9/site-packages/telegram/utils/request.py", line 242, in _request_wrapper
    raise Conflict(message)
telegram.error.Conflict: Conflict: terminated by other getUpdates request; make sure that only one bot instance is running
telegram.ext.updater - INFO - Received signal 2 (SIGINT), stopping...
telegram.ext.updater - INFO - Received signal 2 (SIGINT), stopping...
telegram.ext.updater - INFO - Received signal 2 (SIGINT), stopping...
telegram.ext.updater - INFO - Received signal 2 (SIGINT), stopping...
telegram.ext.dispatcher - ERROR - No error handlers are registered, logging exception.
Traceback (most recent call last):
  File "/Users/konstantin_slepchenko/PycharmProjects/mbot/venv/lib/python3.9/site-packages/telegram/ext/dispatcher.py", line 372, in process_update
    handler.handle_update(update, self, check, context)
  File "/Users/konstantin_slepchenko/PycharmProjects/mbot/venv/lib/python3.9/site-packages/telegram/ext/handler.py", line 120, in handle_update
    return self.callback(dispatcher.bot, update, **optional_args)
  File "/Users/konstantin_slepchenko/PycharmProjects/mbot/mbot_app/miklyx_bot.py", line 142, in bottles_section
    update.message.reply_text(reply_markup=menu_keyboard)
  File "/Users/konstantin_slepchenko/PycharmProjects/mbot/venv/lib/python3.9/site-packages/telegram/message.py", line 478, in reply_text
    return self.bot.send_message(self.chat_id, *args, **kwargs)
  File "/Users/konstantin_slepchenko/PycharmProjects/mbot/venv/lib/python3.9/site-packages/telegram/bot.py", line 66, in decorator
    result = func(self, *args, **kwargs)
TypeError: send_message() missing 1 required positional argument: 'text'
telegram.ext.updater - INFO - Received signal 2 (SIGINT), stopping...
telegram.ext.updater - INFO - Received signal 2 (SIGINT), stopping...
telegram.ext.dispatcher - ERROR - No error handlers are registered, logging exception.
Traceback (most recent call last):
  File "/Users/konstantin_slepchenko/PycharmProjects/mbot/venv/lib/python3.9/site-packages/telegram/ext/dispatcher.py", line 372, in process_update
    handler.handle_update(update, self, check, context)
  File "/Users/konstantin_slepchenko/PycharmProjects/mbot/venv/lib/python3.9/site-packages/telegram/ext/handler.py", line 120, in handle_update
    return self.callback(dispatcher.bot, update, **optional_args)
  File "/Users/konstantin_slepchenko/PycharmProjects/mbot/mbot_app/miklyx_bot.py", line 135, in bottles_section
    result = text['bottle_name'].get(sect[1:].replace(' ', ''))
KeyError: 'bottle_name'
telegram.ext.updater - INFO - Received signal 2 (SIGINT), stopping...
telegram.ext.updater - INFO - Received signal 2 (SIGINT), stopping...
telegram.ext.updater - INFO - Received signal 2 (SIGINT), stopping...
telegram.ext.updater - INFO - Received signal 2 (SIGINT), stopping...
telegram.ext.dispatcher - ERROR - No error handlers are registered, logging exception.
Traceback (most recent call last):
  File "/Users/konstantin_slepchenko/PycharmProjects/mbot/venv/lib/python3.9/site-packages/telegram/ext/dispatcher.py", line 372, in process_update
    handler.handle_update(update, self, check, context)
  File "/Users/konstantin_slepchenko/PycharmProjects/mbot/venv/lib/python3.9/site-packages/telegram/ext/handler.py", line 120, in handle_update
    return self.callback(dispatcher.bot, update, **optional_args)
  File "/Users/konstantin_slepchenko/PycharmProjects/mbot/mbot_app/miklyx_bot.py", line 47, in taps
    update.message.reply_text(reply_markup=menu_keyboard)
  File "/Users/konstantin_slepchenko/PycharmProjects/mbot/venv/lib/python3.9/site-packages/telegram/message.py", line 478, in reply_text
    return self.bot.send_message(self.chat_id, *args, **kwargs)
  File "/Users/konstantin_slepchenko/PycharmProjects/mbot/venv/lib/python3.9/site-packages/telegram/bot.py", line 66, in decorator
    result = func(self, *args, **kwargs)
TypeError: send_message() missing 1 required positional argument: 'text'
telegram.ext.dispatcher - ERROR - No error handlers are registered, logging exception.
Traceback (most recent call last):
  File "/Users/konstantin_slepchenko/PycharmProjects/mbot/venv/lib/python3.9/site-packages/telegram/ext/dispatcher.py", line 372, in process_update
    handler.handle_update(update, self, check, context)
  File "/Users/konstantin_slepchenko/PycharmProjects/mbot/venv/lib/python3.9/site-packages/telegram/ext/handler.py", line 120, in handle_update
    return self.callback(dispatcher.bot, update, **optional_args)
  File "/Users/konstantin_slepchenko/PycharmProjects/mbot/mbot_app/miklyx_bot.py", line 55, in add_button
    c = add_to_cart(update.effective_user, t_id)
  File "/Users/konstantin_slepchenko/PycharmProjects/mbot/mbot_app/service/get_from_db.py", line 76, in add_to_cart
    if db.carts.find_one({'user_id': user_id, 'active_flag': 1}):
  File "/Users/konstantin_slepchenko/PycharmProjects/mbot/venv/lib/python3.9/site-packages/pymongo/collection.py", line 1459, in find_one
    for result in cursor.limit(-1):
  File "/Users/konstantin_slepchenko/PycharmProjects/mbot/venv/lib/python3.9/site-packages/pymongo/cursor.py", line 1248, in next
    if len(self.__data) or self._refresh():
  File "/Users/konstantin_slepchenko/PycharmProjects/mbot/venv/lib/python3.9/site-packages/pymongo/cursor.py", line 1165, in _refresh
    self.__send_message(q)
  File "/Users/konstantin_slepchenko/PycharmProjects/mbot/venv/lib/python3.9/site-packages/pymongo/cursor.py", line 1052, in __send_message
    response = client._run_operation(
  File "/Users/konstantin_slepchenko/PycharmProjects/mbot/venv/lib/python3.9/site-packages/pymongo/_csot.py", line 105, in csot_wrapper
    return func(self, *args, **kwargs)
  File "/Users/konstantin_slepchenko/PycharmProjects/mbot/venv/lib/python3.9/site-packages/pymongo/mongo_client.py", line 1330, in _run_operation
    return self._retryable_read(
  File "/Users/konstantin_slepchenko/PycharmProjects/mbot/venv/lib/python3.9/site-packages/pymongo/_csot.py", line 105, in csot_wrapper
    return func(self, *args, **kwargs)
  File "/Users/konstantin_slepchenko/PycharmProjects/mbot/venv/lib/python3.9/site-packages/pymongo/mongo_client.py", line 1448, in _retryable_read
    return func(session, server, sock_info, read_pref)
  File "/Users/konstantin_slepchenko/PycharmProjects/mbot/venv/lib/python3.9/site-packages/pymongo/mongo_client.py", line 1326, in _cmd
    return server.run_operation(
  File "/Users/konstantin_slepchenko/PycharmProjects/mbot/venv/lib/python3.9/site-packages/pymongo/server.py", line 100, in run_operation
    message = operation.get_message(read_preference, sock_info, use_cmd)
  File "/Users/konstantin_slepchenko/PycharmProjects/mbot/venv/lib/python3.9/site-packages/pymongo/message.py", line 388, in get_message
    request_id, msg, size, _ = _op_msg(
  File "/Users/konstantin_slepchenko/PycharmProjects/mbot/venv/lib/python3.9/site-packages/pymongo/message.py", line 692, in _op_msg
    return _op_msg_uncompressed(flags, command, identifier, docs, opts)
bson.errors.InvalidDocument: cannot encode object: <telegram.user.User object at 0x102e62fa0>, of type: <class 'telegram.user.User'>
telegram.ext.dispatcher - ERROR - No error handlers are registered, logging exception.
Traceback (most recent call last):
  File "/Users/konstantin_slepchenko/PycharmProjects/mbot/venv/lib/python3.9/site-packages/telegram/ext/dispatcher.py", line 372, in process_update
    handler.handle_update(update, self, check, context)
  File "/Users/konstantin_slepchenko/PycharmProjects/mbot/venv/lib/python3.9/site-packages/telegram/ext/handler.py", line 120, in handle_update
    return self.callback(dispatcher.bot, update, **optional_args)
  File "/Users/konstantin_slepchenko/PycharmProjects/mbot/mbot_app/miklyx_bot.py", line 158, in cart
    cart = checkout_cart(update.effective_user, update.effective_user)
  File "/Users/konstantin_slepchenko/PycharmProjects/mbot/mbot_app/service/get_from_db.py", line 158, in checkout_cart
    for j in current_cart['cart']:
TypeError: 'NoneType' object is not subscriptable
telegram.ext.updater - INFO - Received signal 2 (SIGINT), stopping...
telegram.ext.dispatcher - ERROR - No error handlers are registered, logging exception.
Traceback (most recent call last):
  File "/Users/konstantin_slepchenko/PycharmProjects/mbot/venv/lib/python3.9/site-packages/telegram/ext/dispatcher.py", line 372, in process_update
    handler.handle_update(update, self, check, context)
  File "/Users/konstantin_slepchenko/PycharmProjects/mbot/venv/lib/python3.9/site-packages/telegram/ext/handler.py", line 120, in handle_update
    return self.callback(dispatcher.bot, update, **optional_args)
  File "/Users/konstantin_slepchenko/PycharmProjects/mbot/mbot_app/miklyx_bot.py", line 158, in cart
    cart = checkout_cart(update.effective_user, update.effective_user)
  File "/Users/konstantin_slepchenko/PycharmProjects/mbot/mbot_app/service/get_from_db.py", line 158, in checkout_cart
    for j in current_cart['cart']:
TypeError: 'NoneType' object is not subscriptable
telegram.ext.updater - INFO - Received signal 2 (SIGINT), stopping...
telegram.ext.updater - INFO - Received signal 2 (SIGINT), stopping...
telegram.ext.updater - INFO - Received signal 2 (SIGINT), stopping...
telegram.ext.updater - INFO - Received signal 2 (SIGINT), stopping...
telegram.ext.updater - INFO - Received signal 2 (SIGINT), stopping...
telegram.ext.updater - INFO - Received signal 2 (SIGINT), stopping...
telegram.ext.updater - INFO - Received signal 2 (SIGINT), stopping...
telegram.ext.updater - INFO - Received signal 2 (SIGINT), stopping...
telegram.ext.updater - INFO - Received signal 2 (SIGINT), stopping...
telegram.ext.updater - INFO - Received signal 2 (SIGINT), stopping...
telegram.ext.dispatcher - ERROR - No error handlers are registered, logging exception.
Traceback (most recent call last):
  File "/Users/konstantin_slepchenko/PycharmProjects/mbot/venv/lib/python3.9/site-packages/telegram/ext/dispatcher.py", line 372, in process_update
    handler.handle_update(update, self, check, context)
  File "/Users/konstantin_slepchenko/PycharmProjects/mbot/venv/lib/python3.9/site-packages/telegram/ext/handler.py", line 120, in handle_update
    return self.callback(dispatcher.bot, update, **optional_args)
  File "/Users/konstantin_slepchenko/PycharmProjects/mbot/mbot_app/miklyx_bot.py", line 167, in registration
    update.message.reply_text(reply_markup=menu_keyboard)
  File "/Users/konstantin_slepchenko/PycharmProjects/mbot/venv/lib/python3.9/site-packages/telegram/message.py", line 478, in reply_text
    return self.bot.send_message(self.chat_id, *args, **kwargs)
  File "/Users/konstantin_slepchenko/PycharmProjects/mbot/venv/lib/python3.9/site-packages/telegram/bot.py", line 66, in decorator
    result = func(self, *args, **kwargs)
TypeError: send_message() missing 1 required positional argument: 'text'
telegram.ext.dispatcher - ERROR - No error handlers are registered, logging exception.
Traceback (most recent call last):
  File "/Users/konstantin_slepchenko/PycharmProjects/mbot/venv/lib/python3.9/site-packages/telegram/ext/dispatcher.py", line 372, in process_update
    handler.handle_update(update, self, check, context)
  File "/Users/konstantin_slepchenko/PycharmProjects/mbot/venv/lib/python3.9/site-packages/telegram/ext/handler.py", line 120, in handle_update
    return self.callback(dispatcher.bot, update, **optional_args)
  File "/Users/konstantin_slepchenko/PycharmProjects/mbot/mbot_app/miklyx_bot.py", line 167, in registration
    update.message.reply_text(reply_markup=menu_keyboard)
  File "/Users/konstantin_slepchenko/PycharmProjects/mbot/venv/lib/python3.9/site-packages/telegram/message.py", line 478, in reply_text
    return self.bot.send_message(self.chat_id, *args, **kwargs)
  File "/Users/konstantin_slepchenko/PycharmProjects/mbot/venv/lib/python3.9/site-packages/telegram/bot.py", line 66, in decorator
    result = func(self, *args, **kwargs)
TypeError: send_message() missing 1 required positional argument: 'text'
telegram.ext.updater - INFO - Received signal 2 (SIGINT), stopping...
telegram.ext.dispatcher - ERROR - No error handlers are registered, logging exception.
Traceback (most recent call last):
  File "/Users/konstantin_slepchenko/PycharmProjects/mbot/venv/lib/python3.9/site-packages/telegram/ext/dispatcher.py", line 372, in process_update
    handler.handle_update(update, self, check, context)
  File "/Users/konstantin_slepchenko/PycharmProjects/mbot/venv/lib/python3.9/site-packages/telegram/ext/handler.py", line 120, in handle_update
    return self.callback(dispatcher.bot, update, **optional_args)
  File "/Users/konstantin_slepchenko/PycharmProjects/mbot/mbot_app/miklyx_bot.py", line 135, in bottles_section
    if k['bottle_name'] == sect[1:]:
TypeError: 'NoneType' object is not subscriptable
telegram.ext.updater - INFO - Received signal 2 (SIGINT), stopping...
telegram.ext.updater - INFO - Received signal 2 (SIGINT), stopping...
telegram.ext.dispatcher - ERROR - No error handlers are registered, logging exception.
Traceback (most recent call last):
  File "/Users/konstantin_slepchenko/PycharmProjects/mbot/venv/lib/python3.9/site-packages/telegram/ext/dispatcher.py", line 372, in process_update
    handler.handle_update(update, self, check, context)
  File "/Users/konstantin_slepchenko/PycharmProjects/mbot/venv/lib/python3.9/site-packages/telegram/ext/handler.py", line 120, in handle_update
    return self.callback(dispatcher.bot, update, **optional_args)
TypeError: proceed_registration() got an unexpected keyword argument 'user_data'
telegram.ext.dispatcher - ERROR - No error handlers are registered, logging exception.
Traceback (most recent call last):
  File "/Users/konstantin_slepchenko/PycharmProjects/mbot/venv/lib/python3.9/site-packages/telegram/ext/dispatcher.py", line 372, in process_update
    handler.handle_update(update, self, check, context)
  File "/Users/konstantin_slepchenko/PycharmProjects/mbot/venv/lib/python3.9/site-packages/telegram/ext/handler.py", line 120, in handle_update
    return self.callback(dispatcher.bot, update, **optional_args)
TypeError: proceed_registration() got an unexpected keyword argument 'user_data'
telegram.ext.updater - INFO - Received signal 2 (SIGINT), stopping...
telegram.ext.updater - INFO - Received signal 2 (SIGINT), stopping...
telegram.ext.updater - INFO - Received signal 2 (SIGINT), stopping...
telegram.ext.updater - INFO - Received signal 2 (SIGINT), stopping...
telegram.ext.dispatcher - ERROR - No error handlers are registered, logging exception.
Traceback (most recent call last):
  File "/Users/konstantin_slepchenko/PycharmProjects/mbot/venv/lib/python3.9/site-packages/telegram/ext/dispatcher.py", line 372, in process_update
    handler.handle_update(update, self, check, context)
  File "/Users/konstantin_slepchenko/PycharmProjects/mbot/venv/lib/python3.9/site-packages/telegram/ext/handler.py", line 120, in handle_update
    return self.callback(dispatcher.bot, update, **optional_args)
  File "/Users/konstantin_slepchenko/PycharmProjects/mbot/mbot_app/miklyx_bot.py", line 174, in proceed_registration
    write_new_user(update.message)
  File "/Users/konstantin_slepchenko/PycharmProjects/mbot/mbot_app/service/get_from_db.py", line 107, in write_new_user
    username=user.effective_attachment.get('username'),
AttributeError: 'Contact' object has no attribute 'get'
telegram.ext.dispatcher - ERROR - No error handlers are registered, logging exception.
Traceback (most recent call last):
  File "/Users/konstantin_slepchenko/PycharmProjects/mbot/venv/lib/python3.9/site-packages/telegram/ext/dispatcher.py", line 372, in process_update
    handler.handle_update(update, self, check, context)
  File "/Users/konstantin_slepchenko/PycharmProjects/mbot/venv/lib/python3.9/site-packages/telegram/ext/handler.py", line 120, in handle_update
    return self.callback(dispatcher.bot, update, **optional_args)
  File "/Users/konstantin_slepchenko/PycharmProjects/mbot/mbot_app/miklyx_bot.py", line 174, in proceed_registration
    write_new_user(update.message)
  File "/Users/konstantin_slepchenko/PycharmProjects/mbot/mbot_app/service/get_from_db.py", line 107, in write_new_user
    username=user.effective_attachment.get('username'),
AttributeError: 'Contact' object has no attribute 'get'
telegram.ext.updater - INFO - Received signal 2 (SIGINT), stopping...
telegram.ext.dispatcher - ERROR - No error handlers are registered, logging exception.
Traceback (most recent call last):
  File "/Users/konstantin_slepchenko/PycharmProjects/mbot/venv/lib/python3.9/site-packages/telegram/ext/dispatcher.py", line 372, in process_update
    handler.handle_update(update, self, check, context)
  File "/Users/konstantin_slepchenko/PycharmProjects/mbot/venv/lib/python3.9/site-packages/telegram/ext/handler.py", line 120, in handle_update
    return self.callback(dispatcher.bot, update, **optional_args)
  File "/Users/konstantin_slepchenko/PycharmProjects/mbot/mbot_app/miklyx_bot.py", line 174, in proceed_registration
    write_new_user(update.message)
  File "/Users/konstantin_slepchenko/PycharmProjects/mbot/mbot_app/service/get_from_db.py", line 107, in write_new_user
    username=user.effective_attachment.get('username'),
AttributeError: 'Contact' object has no attribute 'get'
telegram.ext.updater - INFO - Received signal 2 (SIGINT), stopping...
telegram.ext.dispatcher - ERROR - No error handlers are registered, logging exception.
Traceback (most recent call last):
  File "/Users/konstantin_slepchenko/PycharmProjects/mbot/venv/lib/python3.9/site-packages/telegram/ext/dispatcher.py", line 372, in process_update
    handler.handle_update(update, self, check, context)
  File "/Users/konstantin_slepchenko/PycharmProjects/mbot/venv/lib/python3.9/site-packages/telegram/ext/handler.py", line 120, in handle_update
    return self.callback(dispatcher.bot, update, **optional_args)
  File "/Users/konstantin_slepchenko/PycharmProjects/mbot/mbot_app/miklyx_bot.py", line 174, in proceed_registration
    write_new_user(update.message)
  File "/Users/konstantin_slepchenko/PycharmProjects/mbot/mbot_app/service/get_from_db.py", line 107, in write_new_user
    username=user.effective_user.username,
AttributeError: 'Message' object has no attribute 'effective_user'
telegram.ext.dispatcher - ERROR - No error handlers are registered, logging exception.
Traceback (most recent call last):
  File "/Users/konstantin_slepchenko/PycharmProjects/mbot/venv/lib/python3.9/site-packages/telegram/ext/dispatcher.py", line 372, in process_update
    handler.handle_update(update, self, check, context)
  File "/Users/konstantin_slepchenko/PycharmProjects/mbot/venv/lib/python3.9/site-packages/telegram/ext/handler.py", line 120, in handle_update
    return self.callback(dispatcher.bot, update, **optional_args)
  File "/Users/konstantin_slepchenko/PycharmProjects/mbot/mbot_app/miklyx_bot.py", line 174, in proceed_registration
    write_new_user(update.message)
  File "/Users/konstantin_slepchenko/PycharmProjects/mbot/mbot_app/service/get_from_db.py", line 107, in write_new_user
    username=user.effective_user.username,
AttributeError: 'Message' object has no attribute 'effective_user'
telegram.ext.updater - INFO - Received signal 2 (SIGINT), stopping...
telegram.ext.dispatcher - ERROR - No error handlers are registered, logging exception.
Traceback (most recent call last):
  File "/Users/konstantin_slepchenko/PycharmProjects/mbot/venv/lib/python3.9/site-packages/telegram/ext/dispatcher.py", line 372, in process_update
    handler.handle_update(update, self, check, context)
  File "/Users/konstantin_slepchenko/PycharmProjects/mbot/venv/lib/python3.9/site-packages/telegram/ext/handler.py", line 120, in handle_update
    return self.callback(dispatcher.bot, update, **optional_args)
  File "/Users/konstantin_slepchenko/PycharmProjects/mbot/mbot_app/miklyx_bot.py", line 174, in proceed_registration
    write_new_user(update.message)
  File "/Users/konstantin_slepchenko/PycharmProjects/mbot/mbot_app/service/get_from_db.py", line 113, in write_new_user
    db.users.insert_one({user_data.__dict__})
TypeError: unhashable type: 'dict'
telegram.ext.updater - INFO - Received signal 2 (SIGINT), stopping...
telegram.ext.updater - INFO - Received signal 2 (SIGINT), stopping...
telegram.ext.updater - INFO - Received signal 2 (SIGINT), stopping...
telegram.ext.updater - INFO - Received signal 2 (SIGINT), stopping...
telegram.ext.updater - INFO - Received signal 2 (SIGINT), stopping...
telegram.ext.updater - INFO - Received signal 2 (SIGINT), stopping...
telegram.ext.updater - INFO - Received signal 2 (SIGINT), stopping...
telegram.ext.updater - INFO - Received signal 2 (SIGINT), stopping...
telegram.ext.updater - INFO - Received signal 2 (SIGINT), stopping...
telegram.ext.updater - INFO - Received signal 2 (SIGINT), stopping...
telegram.ext.updater - INFO - Received signal 2 (SIGINT), stopping...
telegram.ext.updater - INFO - Received signal 2 (SIGINT), stopping...
telegram.ext.updater - INFO - Received signal 2 (SIGINT), stopping...
telegram.ext.updater - INFO - Received signal 2 (SIGINT), stopping...
telegram.ext.updater - INFO - Received signal 2 (SIGINT), stopping...
telegram.ext.updater - INFO - Received signal 2 (SIGINT), stopping...
telegram.ext.updater - INFO - Received signal 2 (SIGINT), stopping...
telegram.ext.updater - INFO - Received signal 2 (SIGINT), stopping...
